2022-02-22 22:43:21,769 INFO    MainThread:37184 [internal.py:wandb_internal():87] W&B internal server running at pid: 37184, started at: 2022-02-22 22:43:21.768243
2022-02-22 22:43:21,771 INFO    WriterThread:37184 [datastore.py:open_for_write():77] open: E:\learn\github_project\yolov5-face\wandb\run-20220222_224320-38ghlcy7\run-38ghlcy7.wandb
2022-02-22 22:43:21,771 DEBUG   HandlerThread:37184 [handler.py:handle_request():130] handle_request: check_version
2022-02-22 22:43:21,772 DEBUG   SenderThread:37184 [sender.py:send():234] send: header
2022-02-22 22:43:21,773 DEBUG   SenderThread:37184 [sender.py:send_request():248] send_request: check_version
2022-02-22 22:43:21,797 DEBUG   SenderThread:37184 [sender.py:send():234] send: run
2022-02-22 22:43:21,808 INFO    SenderThread:37184 [sender.py:_maybe_setup_resume():484] checking resume status for None/YOLOv5/38ghlcy7
2022-02-22 22:43:25,422 ERROR   SenderThread:37184 [retry.py:__call__():126] Retry attempt failed:
Traceback (most recent call last):
  File "C:\ProgramData\Anaconda3\envs\pytorch171\lib\site-packages\urllib3\connectionpool.py", line 696, in urlopen
    self._prepare_proxy(conn)
  File "C:\ProgramData\Anaconda3\envs\pytorch171\lib\site-packages\urllib3\connectionpool.py", line 964, in _prepare_proxy
    conn.connect()
  File "C:\ProgramData\Anaconda3\envs\pytorch171\lib\site-packages\urllib3\connection.py", line 364, in connect
    conn = self._connect_tls_proxy(hostname, conn)
  File "C:\ProgramData\Anaconda3\envs\pytorch171\lib\site-packages\urllib3\connection.py", line 501, in _connect_tls_proxy
    socket = ssl_wrap_socket(
  File "C:\ProgramData\Anaconda3\envs\pytorch171\lib\site-packages\urllib3\util\ssl_.py", line 453, in ssl_wrap_socket
    ssl_sock = _ssl_wrap_socket_impl(sock, context, tls_in_tls)
  File "C:\ProgramData\Anaconda3\envs\pytorch171\lib\site-packages\urllib3\util\ssl_.py", line 495, in _ssl_wrap_socket_impl
    return ssl_context.wrap_socket(sock)
  File "C:\ProgramData\Anaconda3\envs\pytorch171\lib\ssl.py", line 500, in wrap_socket
    return self.sslsocket_class._create(
  File "C:\ProgramData\Anaconda3\envs\pytorch171\lib\ssl.py", line 1040, in _create
    self.do_handshake()
  File "C:\ProgramData\Anaconda3\envs\pytorch171\lib\ssl.py", line 1309, in do_handshake
    self._sslobj.do_handshake()
ssl.SSLEOFError: EOF occurred in violation of protocol (_ssl.c:1131)

During handling of the above exception, another exception occurred:

Traceback (most recent call last):
  File "C:\ProgramData\Anaconda3\envs\pytorch171\lib\site-packages\requests\adapters.py", line 439, in send
    resp = conn.urlopen(
  File "C:\ProgramData\Anaconda3\envs\pytorch171\lib\site-packages\urllib3\connectionpool.py", line 755, in urlopen
    retries = retries.increment(
  File "C:\ProgramData\Anaconda3\envs\pytorch171\lib\site-packages\urllib3\util\retry.py", line 574, in increment
    raise MaxRetryError(_pool, url, error or ResponseError(cause))
urllib3.exceptions.MaxRetryError: HTTPSConnectionPool(host='api.wandb.ai', port=443): Max retries exceeded with url: /graphql (Caused by SSLError(SSLEOFError(8, 'EOF occurred in violation of protocol (_ssl.c:1131)')))

During handling of the above exception, another exception occurred:

Traceback (most recent call last):
  File "C:\ProgramData\Anaconda3\envs\pytorch171\lib\site-packages\wandb\sdk\lib\retry.py", line 102, in __call__
    result = self._call_fn(*args, **kwargs)
  File "C:\ProgramData\Anaconda3\envs\pytorch171\lib\site-packages\wandb\sdk\internal\internal_api.py", line 141, in execute
    return self.client.execute(*args, **kwargs)
  File "C:\ProgramData\Anaconda3\envs\pytorch171\lib\site-packages\wandb\vendor\gql-0.2.0\gql\client.py", line 52, in execute
    result = self._get_result(document, *args, **kwargs)
  File "C:\ProgramData\Anaconda3\envs\pytorch171\lib\site-packages\wandb\vendor\gql-0.2.0\gql\client.py", line 60, in _get_result
    return self.transport.execute(document, *args, **kwargs)
  File "C:\ProgramData\Anaconda3\envs\pytorch171\lib\site-packages\wandb\vendor\gql-0.2.0\gql\transport\requests.py", line 38, in execute
    request = requests.post(self.url, **post_args)
  File "C:\ProgramData\Anaconda3\envs\pytorch171\lib\site-packages\requests\api.py", line 119, in post
    return request('post', url, data=data, json=json, **kwargs)
  File "C:\ProgramData\Anaconda3\envs\pytorch171\lib\site-packages\requests\api.py", line 61, in request
    return session.request(method=method, url=url, **kwargs)
  File "C:\ProgramData\Anaconda3\envs\pytorch171\lib\site-packages\requests\sessions.py", line 542, in request
    resp = self.send(prep, **send_kwargs)
  File "C:\ProgramData\Anaconda3\envs\pytorch171\lib\site-packages\requests\sessions.py", line 655, in send
    r = adapter.send(request, **kwargs)
  File "C:\ProgramData\Anaconda3\envs\pytorch171\lib\site-packages\requests\adapters.py", line 514, in send
    raise SSLError(e, request=request)
requests.exceptions.SSLError: HTTPSConnectionPool(host='api.wandb.ai', port=443): Max retries exceeded with url: /graphql (Caused by SSLError(SSLEOFError(8, 'EOF occurred in violation of protocol (_ssl.c:1131)')))
2022-02-22 22:43:51,797 DEBUG   HandlerThread:37184 [handler.py:handle_request():130] handle_request: shutdown
2022-02-22 22:43:51,797 INFO    HandlerThread:37184 [handler.py:finish():731] shutting down handler
2022-02-22 22:43:51,821 INFO    WriterThread:37184 [datastore.py:close():281] close: E:\learn\github_project\yolov5-face\wandb\run-20220222_224320-38ghlcy7\run-38ghlcy7.wandb
