2022-02-22 23:41:47,246 INFO    MainThread:20604 [internal.py:wandb_internal():87] W&B internal server running at pid: 20604, started at: 2022-02-22 23:41:47.245505
2022-02-22 23:41:47,250 DEBUG   HandlerThread:20604 [handler.py:handle_request():130] handle_request: check_version
2022-02-22 23:41:47,250 INFO    WriterThread:20604 [datastore.py:open_for_write():77] open: E:\learn\github_project\yolov5-face\wandb\run-20220222_234144-12vj7711\run-12vj7711.wandb
2022-02-22 23:41:47,283 DEBUG   SenderThread:20604 [sender.py:send():234] send: header
2022-02-22 23:41:47,284 DEBUG   SenderThread:20604 [sender.py:send_request():248] send_request: check_version
2022-02-22 23:41:47,729 DEBUG   SenderThread:20604 [sender.py:send():234] send: run
2022-02-22 23:41:47,760 INFO    SenderThread:20604 [sender.py:_maybe_setup_resume():484] checking resume status for None/YOLOv5/12vj7711
2022-02-22 23:41:48,648 INFO    SenderThread:20604 [dir_watcher.py:__init__():169] watching files in: E:\learn\github_project\yolov5-face\wandb\run-20220222_234144-12vj7711\files
2022-02-22 23:41:48,649 INFO    SenderThread:20604 [sender.py:_start_run_threads():804] run started: 12vj7711 with start time 1645544506
2022-02-22 23:41:48,649 DEBUG   SenderThread:20604 [sender.py:send():234] send: summary
2022-02-22 23:41:48,650 INFO    SenderThread:20604 [sender.py:_save_file():939] saving file wandb-summary.json with policy end
2022-02-22 23:41:48,655 DEBUG   HandlerThread:20604 [handler.py:handle_request():130] handle_request: run_start
2022-02-22 23:41:48,687 DEBUG   HandlerThread:20604 [meta.py:__init__():40] meta init
2022-02-22 23:41:48,687 DEBUG   HandlerThread:20604 [meta.py:__init__():54] meta init done
2022-02-22 23:41:48,687 DEBUG   HandlerThread:20604 [meta.py:probe():214] probe
2022-02-22 23:41:48,767 DEBUG   HandlerThread:20604 [git.py:repo():33] git repository is invalid
2022-02-22 23:41:48,767 DEBUG   HandlerThread:20604 [meta.py:_save_pip():58] save pip
2022-02-22 23:41:48,771 DEBUG   HandlerThread:20604 [meta.py:_save_pip():72] save pip done
2022-02-22 23:41:48,771 DEBUG   HandlerThread:20604 [meta.py:_save_conda():79] save conda
2022-02-22 23:41:49,654 INFO    Thread-17 :20604 [dir_watcher.py:_on_file_created():217] file/dir created: E:\learn\github_project\yolov5-face\wandb\run-20220222_234144-12vj7711\files\requirements.txt
2022-02-22 23:41:49,655 INFO    Thread-17 :20604 [dir_watcher.py:_on_file_created():217] file/dir created: E:\learn\github_project\yolov5-face\wandb\run-20220222_234144-12vj7711\files\wandb-summary.json
2022-02-22 23:41:49,656 INFO    Thread-17 :20604 [dir_watcher.py:_on_file_created():217] file/dir created: E:\learn\github_project\yolov5-face\wandb\run-20220222_234144-12vj7711\files\conda-environment.yaml
2022-02-22 23:41:54,664 INFO    Thread-17 :20604 [dir_watcher.py:_on_file_created():217] file/dir created: E:\learn\github_project\yolov5-face\wandb\run-20220222_234144-12vj7711\files\output.log
2022-02-22 23:41:55,881 DEBUG   HandlerThread:20604 [meta.py:_save_conda():89] save conda done
2022-02-22 23:41:55,881 DEBUG   HandlerThread:20604 [meta.py:probe():252] probe done
2022-02-22 23:41:56,398 DEBUG   HandlerThread:20604 [handler.py:handle_request():130] handle_request: stop_status
2022-02-22 23:41:56,398 DEBUG   SenderThread:20604 [sender.py:send_request():248] send_request: stop_status
2022-02-22 23:41:56,667 INFO    Thread-17 :20604 [dir_watcher.py:_on_file_modified():230] file/dir modified: E:\learn\github_project\yolov5-face\wandb\run-20220222_234144-12vj7711\files\conda-environment.yaml
2022-02-22 23:41:56,667 INFO    Thread-17 :20604 [dir_watcher.py:_on_file_created():217] file/dir created: E:\learn\github_project\yolov5-face\wandb\run-20220222_234144-12vj7711\files\wandb-metadata.json
2022-02-22 23:41:56,773 DEBUG   SenderThread:20604 [sender.py:send():234] send: files
2022-02-22 23:41:56,774 INFO    SenderThread:20604 [sender.py:_save_file():939] saving file wandb-metadata.json with policy now
2022-02-22 23:41:57,206 ERROR   Thread-20 :20604 [internal_api.py:upload_file():1574] upload_file exception https://storage.googleapis.com/wandb-production.appspot.com/heene/YOLOv5/12vj7711/wandb-metadata.json?Expires=1645630917&GoogleAccessId=wandb-production%40appspot.gserviceaccount.com&Signature=j88Eu9tD9cNM6xXz9C9ZXh24udpgjFtIE8HWtSRnr316PdLJ%2BF615aRVCArBK6M%2Bl5p7VfY81mS4gTmSOCDdTI8nuSCrrljLWWzy5iDoJQEuRKRBy1uT%2Ba9JlRQANDYBQkyH3Xb6yvrQgcrFmL0Xc9lWkAB3wd%2FA6zh5zlm2cFJ7eGvlaD%2BQyDhfhfG%2BgnFa7Y7cP%2FSXg7nn4RKilBt2VOfIb1kYJPR36xOoeKuJO3%2BWvF7xo2Zlpg6%2BtTiD4HKNuO9FOlj4O7BfAerZYPEI5QNFa286yjbRHFr7WJhpGrJSUnGVd4pHXD7mRJDACcpu4SUHPJ3uIt15azbhlhoxHQ%3D%3D: HTTPSConnectionPool(host='storage.googleapis.com', port=443): Max retries exceeded with url: /wandb-production.appspot.com/heene/YOLOv5/12vj7711/wandb-metadata.json?Expires=1645630917&GoogleAccessId=wandb-production%40appspot.gserviceaccount.com&Signature=j88Eu9tD9cNM6xXz9C9ZXh24udpgjFtIE8HWtSRnr316PdLJ%2BF615aRVCArBK6M%2Bl5p7VfY81mS4gTmSOCDdTI8nuSCrrljLWWzy5iDoJQEuRKRBy1uT%2Ba9JlRQANDYBQkyH3Xb6yvrQgcrFmL0Xc9lWkAB3wd%2FA6zh5zlm2cFJ7eGvlaD%2BQyDhfhfG%2BgnFa7Y7cP%2FSXg7nn4RKilBt2VOfIb1kYJPR36xOoeKuJO3%2BWvF7xo2Zlpg6%2BtTiD4HKNuO9FOlj4O7BfAerZYPEI5QNFa286yjbRHFr7WJhpGrJSUnGVd4pHXD7mRJDACcpu4SUHPJ3uIt15azbhlhoxHQ%3D%3D (Caused by SSLError(SSLEOFError(8, 'EOF occurred in violation of protocol (_ssl.c:1131)')))
2022-02-22 23:41:57,206 ERROR   Thread-20 :20604 [internal_api.py:upload_file():1576] upload_file request headers: {'User-Agent': 'python-requests/2.25.1', 'Accept-Encoding': 'gzip, deflate', 'Accept': '*/*', 'Connection': 'keep-alive', 'Content-Length': '561'}
2022-02-22 23:41:57,206 ERROR   Thread-20 :20604 [internal_api.py:upload_file():1578] upload_file response body: 
2022-02-22 23:41:58,343 ERROR   Thread-20 :20604 [internal_api.py:upload_file():1574] upload_file exception https://storage.googleapis.com/wandb-production.appspot.com/heene/YOLOv5/12vj7711/wandb-metadata.json?Expires=1645630917&GoogleAccessId=wandb-production%40appspot.gserviceaccount.com&Signature=j88Eu9tD9cNM6xXz9C9ZXh24udpgjFtIE8HWtSRnr316PdLJ%2BF615aRVCArBK6M%2Bl5p7VfY81mS4gTmSOCDdTI8nuSCrrljLWWzy5iDoJQEuRKRBy1uT%2Ba9JlRQANDYBQkyH3Xb6yvrQgcrFmL0Xc9lWkAB3wd%2FA6zh5zlm2cFJ7eGvlaD%2BQyDhfhfG%2BgnFa7Y7cP%2FSXg7nn4RKilBt2VOfIb1kYJPR36xOoeKuJO3%2BWvF7xo2Zlpg6%2BtTiD4HKNuO9FOlj4O7BfAerZYPEI5QNFa286yjbRHFr7WJhpGrJSUnGVd4pHXD7mRJDACcpu4SUHPJ3uIt15azbhlhoxHQ%3D%3D: HTTPSConnectionPool(host='storage.googleapis.com', port=443): Max retries exceeded with url: /wandb-production.appspot.com/heene/YOLOv5/12vj7711/wandb-metadata.json?Expires=1645630917&GoogleAccessId=wandb-production%40appspot.gserviceaccount.com&Signature=j88Eu9tD9cNM6xXz9C9ZXh24udpgjFtIE8HWtSRnr316PdLJ%2BF615aRVCArBK6M%2Bl5p7VfY81mS4gTmSOCDdTI8nuSCrrljLWWzy5iDoJQEuRKRBy1uT%2Ba9JlRQANDYBQkyH3Xb6yvrQgcrFmL0Xc9lWkAB3wd%2FA6zh5zlm2cFJ7eGvlaD%2BQyDhfhfG%2BgnFa7Y7cP%2FSXg7nn4RKilBt2VOfIb1kYJPR36xOoeKuJO3%2BWvF7xo2Zlpg6%2BtTiD4HKNuO9FOlj4O7BfAerZYPEI5QNFa286yjbRHFr7WJhpGrJSUnGVd4pHXD7mRJDACcpu4SUHPJ3uIt15azbhlhoxHQ%3D%3D (Caused by SSLError(SSLEOFError(8, 'EOF occurred in violation of protocol (_ssl.c:1131)')))
2022-02-22 23:41:58,343 ERROR   Thread-20 :20604 [internal_api.py:upload_file():1576] upload_file request headers: {'User-Agent': 'python-requests/2.25.1', 'Accept-Encoding': 'gzip, deflate', 'Accept': '*/*', 'Connection': 'keep-alive', 'Content-Length': '561'}
2022-02-22 23:41:58,343 ERROR   Thread-20 :20604 [internal_api.py:upload_file():1578] upload_file response body: 
2022-02-22 23:42:00,662 ERROR   Thread-20 :20604 [internal_api.py:upload_file():1574] upload_file exception https://storage.googleapis.com/wandb-production.appspot.com/heene/YOLOv5/12vj7711/wandb-metadata.json?Expires=1645630917&GoogleAccessId=wandb-production%40appspot.gserviceaccount.com&Signature=j88Eu9tD9cNM6xXz9C9ZXh24udpgjFtIE8HWtSRnr316PdLJ%2BF615aRVCArBK6M%2Bl5p7VfY81mS4gTmSOCDdTI8nuSCrrljLWWzy5iDoJQEuRKRBy1uT%2Ba9JlRQANDYBQkyH3Xb6yvrQgcrFmL0Xc9lWkAB3wd%2FA6zh5zlm2cFJ7eGvlaD%2BQyDhfhfG%2BgnFa7Y7cP%2FSXg7nn4RKilBt2VOfIb1kYJPR36xOoeKuJO3%2BWvF7xo2Zlpg6%2BtTiD4HKNuO9FOlj4O7BfAerZYPEI5QNFa286yjbRHFr7WJhpGrJSUnGVd4pHXD7mRJDACcpu4SUHPJ3uIt15azbhlhoxHQ%3D%3D: HTTPSConnectionPool(host='storage.googleapis.com', port=443): Max retries exceeded with url: /wandb-production.appspot.com/heene/YOLOv5/12vj7711/wandb-metadata.json?Expires=1645630917&GoogleAccessId=wandb-production%40appspot.gserviceaccount.com&Signature=j88Eu9tD9cNM6xXz9C9ZXh24udpgjFtIE8HWtSRnr316PdLJ%2BF615aRVCArBK6M%2Bl5p7VfY81mS4gTmSOCDdTI8nuSCrrljLWWzy5iDoJQEuRKRBy1uT%2Ba9JlRQANDYBQkyH3Xb6yvrQgcrFmL0Xc9lWkAB3wd%2FA6zh5zlm2cFJ7eGvlaD%2BQyDhfhfG%2BgnFa7Y7cP%2FSXg7nn4RKilBt2VOfIb1kYJPR36xOoeKuJO3%2BWvF7xo2Zlpg6%2BtTiD4HKNuO9FOlj4O7BfAerZYPEI5QNFa286yjbRHFr7WJhpGrJSUnGVd4pHXD7mRJDACcpu4SUHPJ3uIt15azbhlhoxHQ%3D%3D (Caused by SSLError(SSLEOFError(8, 'EOF occurred in violation of protocol (_ssl.c:1131)')))
2022-02-22 23:42:00,662 ERROR   Thread-20 :20604 [internal_api.py:upload_file():1576] upload_file request headers: {'User-Agent': 'python-requests/2.25.1', 'Accept-Encoding': 'gzip, deflate', 'Accept': '*/*', 'Connection': 'keep-alive', 'Content-Length': '561'}
2022-02-22 23:42:00,663 ERROR   Thread-20 :20604 [internal_api.py:upload_file():1578] upload_file response body: 
2022-02-22 23:42:00,663 ERROR   Thread-20 :20604 [retry.py:__call__():126] Retry attempt failed:
Traceback (most recent call last):
  File "C:\ProgramData\Anaconda3\envs\pytorch171\lib\site-packages\urllib3\connectionpool.py", line 699, in urlopen
    httplib_response = self._make_request(
  File "C:\ProgramData\Anaconda3\envs\pytorch171\lib\site-packages\urllib3\connectionpool.py", line 382, in _make_request
    self._validate_conn(conn)
  File "C:\ProgramData\Anaconda3\envs\pytorch171\lib\site-packages\urllib3\connectionpool.py", line 1010, in _validate_conn
    conn.connect()
  File "C:\ProgramData\Anaconda3\envs\pytorch171\lib\site-packages\urllib3\connection.py", line 416, in connect
    self.sock = ssl_wrap_socket(
  File "C:\ProgramData\Anaconda3\envs\pytorch171\lib\site-packages\urllib3\util\ssl_.py", line 449, in ssl_wrap_socket
    ssl_sock = _ssl_wrap_socket_impl(
  File "C:\ProgramData\Anaconda3\envs\pytorch171\lib\site-packages\urllib3\util\ssl_.py", line 493, in _ssl_wrap_socket_impl
    return ssl_context.wrap_socket(sock, server_hostname=server_hostname)
  File "C:\ProgramData\Anaconda3\envs\pytorch171\lib\ssl.py", line 500, in wrap_socket
    return self.sslsocket_class._create(
  File "C:\ProgramData\Anaconda3\envs\pytorch171\lib\ssl.py", line 1040, in _create
    self.do_handshake()
  File "C:\ProgramData\Anaconda3\envs\pytorch171\lib\ssl.py", line 1309, in do_handshake
    self._sslobj.do_handshake()
ssl.SSLEOFError: EOF occurred in violation of protocol (_ssl.c:1131)

During handling of the above exception, another exception occurred:

Traceback (most recent call last):
  File "C:\ProgramData\Anaconda3\envs\pytorch171\lib\site-packages\requests\adapters.py", line 439, in send
    resp = conn.urlopen(
  File "C:\ProgramData\Anaconda3\envs\pytorch171\lib\site-packages\urllib3\connectionpool.py", line 755, in urlopen
    retries = retries.increment(
  File "C:\ProgramData\Anaconda3\envs\pytorch171\lib\site-packages\urllib3\util\retry.py", line 574, in increment
    raise MaxRetryError(_pool, url, error or ResponseError(cause))
urllib3.exceptions.MaxRetryError: HTTPSConnectionPool(host='storage.googleapis.com', port=443): Max retries exceeded with url: /wandb-production.appspot.com/heene/YOLOv5/12vj7711/wandb-metadata.json?Expires=1645630917&GoogleAccessId=wandb-production%40appspot.gserviceaccount.com&Signature=j88Eu9tD9cNM6xXz9C9ZXh24udpgjFtIE8HWtSRnr316PdLJ%2BF615aRVCArBK6M%2Bl5p7VfY81mS4gTmSOCDdTI8nuSCrrljLWWzy5iDoJQEuRKRBy1uT%2Ba9JlRQANDYBQkyH3Xb6yvrQgcrFmL0Xc9lWkAB3wd%2FA6zh5zlm2cFJ7eGvlaD%2BQyDhfhfG%2BgnFa7Y7cP%2FSXg7nn4RKilBt2VOfIb1kYJPR36xOoeKuJO3%2BWvF7xo2Zlpg6%2BtTiD4HKNuO9FOlj4O7BfAerZYPEI5QNFa286yjbRHFr7WJhpGrJSUnGVd4pHXD7mRJDACcpu4SUHPJ3uIt15azbhlhoxHQ%3D%3D (Caused by SSLError(SSLEOFError(8, 'EOF occurred in violation of protocol (_ssl.c:1131)')))

During handling of the above exception, another exception occurred:

Traceback (most recent call last):
  File "C:\ProgramData\Anaconda3\envs\pytorch171\lib\site-packages\wandb\sdk\internal\internal_api.py", line 1571, in upload_file
    response = requests.put(url, data=progress, headers=extra_headers)
  File "C:\ProgramData\Anaconda3\envs\pytorch171\lib\site-packages\requests\api.py", line 134, in put
    return request('put', url, data=data, **kwargs)
  File "C:\ProgramData\Anaconda3\envs\pytorch171\lib\site-packages\requests\api.py", line 61, in request
    return session.request(method=method, url=url, **kwargs)
  File "C:\ProgramData\Anaconda3\envs\pytorch171\lib\site-packages\requests\sessions.py", line 542, in request
    resp = self.send(prep, **send_kwargs)
  File "C:\ProgramData\Anaconda3\envs\pytorch171\lib\site-packages\requests\sessions.py", line 655, in send
    r = adapter.send(request, **kwargs)
  File "C:\ProgramData\Anaconda3\envs\pytorch171\lib\site-packages\requests\adapters.py", line 514, in send
    raise SSLError(e, request=request)
requests.exceptions.SSLError: HTTPSConnectionPool(host='storage.googleapis.com', port=443): Max retries exceeded with url: /wandb-production.appspot.com/heene/YOLOv5/12vj7711/wandb-metadata.json?Expires=1645630917&GoogleAccessId=wandb-production%40appspot.gserviceaccount.com&Signature=j88Eu9tD9cNM6xXz9C9ZXh24udpgjFtIE8HWtSRnr316PdLJ%2BF615aRVCArBK6M%2Bl5p7VfY81mS4gTmSOCDdTI8nuSCrrljLWWzy5iDoJQEuRKRBy1uT%2Ba9JlRQANDYBQkyH3Xb6yvrQgcrFmL0Xc9lWkAB3wd%2FA6zh5zlm2cFJ7eGvlaD%2BQyDhfhfG%2BgnFa7Y7cP%2FSXg7nn4RKilBt2VOfIb1kYJPR36xOoeKuJO3%2BWvF7xo2Zlpg6%2BtTiD4HKNuO9FOlj4O7BfAerZYPEI5QNFa286yjbRHFr7WJhpGrJSUnGVd4pHXD7mRJDACcpu4SUHPJ3uIt15azbhlhoxHQ%3D%3D (Caused by SSLError(SSLEOFError(8, 'EOF occurred in violation of protocol (_ssl.c:1131)')))

During handling of the above exception, another exception occurred:

Traceback (most recent call last):
  File "C:\ProgramData\Anaconda3\envs\pytorch171\lib\site-packages\wandb\sdk\lib\retry.py", line 102, in __call__
    result = self._call_fn(*args, **kwargs)
  File "C:\ProgramData\Anaconda3\envs\pytorch171\lib\site-packages\wandb\sdk\internal\internal_api.py", line 1587, in upload_file
    six.reraise(type(e), e, sys.exc_info()[2])
  File "C:\ProgramData\Anaconda3\envs\pytorch171\lib\site-packages\six.py", line 718, in reraise
    raise value.with_traceback(tb)
  File "C:\ProgramData\Anaconda3\envs\pytorch171\lib\site-packages\wandb\sdk\internal\internal_api.py", line 1571, in upload_file
    response = requests.put(url, data=progress, headers=extra_headers)
  File "C:\ProgramData\Anaconda3\envs\pytorch171\lib\site-packages\requests\api.py", line 134, in put
    return request('put', url, data=data, **kwargs)
  File "C:\ProgramData\Anaconda3\envs\pytorch171\lib\site-packages\requests\api.py", line 61, in request
    return session.request(method=method, url=url, **kwargs)
  File "C:\ProgramData\Anaconda3\envs\pytorch171\lib\site-packages\requests\sessions.py", line 542, in request
    resp = self.send(prep, **send_kwargs)
  File "C:\ProgramData\Anaconda3\envs\pytorch171\lib\site-packages\requests\sessions.py", line 655, in send
    r = adapter.send(request, **kwargs)
  File "C:\ProgramData\Anaconda3\envs\pytorch171\lib\site-packages\requests\adapters.py", line 514, in send
    raise SSLError(e, request=request)
wandb.sdk.lib.retry.TransientError: None
2022-02-22 23:42:00,671 INFO    Thread-17 :20604 [dir_watcher.py:_on_file_modified():230] file/dir modified: E:\learn\github_project\yolov5-face\wandb\run-20220222_234144-12vj7711\files\output.log
2022-02-22 23:42:05,483 ERROR   Thread-20 :20604 [internal_api.py:upload_file():1574] upload_file exception https://storage.googleapis.com/wandb-production.appspot.com/heene/YOLOv5/12vj7711/wandb-metadata.json?Expires=1645630917&GoogleAccessId=wandb-production%40appspot.gserviceaccount.com&Signature=j88Eu9tD9cNM6xXz9C9ZXh24udpgjFtIE8HWtSRnr316PdLJ%2BF615aRVCArBK6M%2Bl5p7VfY81mS4gTmSOCDdTI8nuSCrrljLWWzy5iDoJQEuRKRBy1uT%2Ba9JlRQANDYBQkyH3Xb6yvrQgcrFmL0Xc9lWkAB3wd%2FA6zh5zlm2cFJ7eGvlaD%2BQyDhfhfG%2BgnFa7Y7cP%2FSXg7nn4RKilBt2VOfIb1kYJPR36xOoeKuJO3%2BWvF7xo2Zlpg6%2BtTiD4HKNuO9FOlj4O7BfAerZYPEI5QNFa286yjbRHFr7WJhpGrJSUnGVd4pHXD7mRJDACcpu4SUHPJ3uIt15azbhlhoxHQ%3D%3D: HTTPSConnectionPool(host='storage.googleapis.com', port=443): Max retries exceeded with url: /wandb-production.appspot.com/heene/YOLOv5/12vj7711/wandb-metadata.json?Expires=1645630917&GoogleAccessId=wandb-production%40appspot.gserviceaccount.com&Signature=j88Eu9tD9cNM6xXz9C9ZXh24udpgjFtIE8HWtSRnr316PdLJ%2BF615aRVCArBK6M%2Bl5p7VfY81mS4gTmSOCDdTI8nuSCrrljLWWzy5iDoJQEuRKRBy1uT%2Ba9JlRQANDYBQkyH3Xb6yvrQgcrFmL0Xc9lWkAB3wd%2FA6zh5zlm2cFJ7eGvlaD%2BQyDhfhfG%2BgnFa7Y7cP%2FSXg7nn4RKilBt2VOfIb1kYJPR36xOoeKuJO3%2BWvF7xo2Zlpg6%2BtTiD4HKNuO9FOlj4O7BfAerZYPEI5QNFa286yjbRHFr7WJhpGrJSUnGVd4pHXD7mRJDACcpu4SUHPJ3uIt15azbhlhoxHQ%3D%3D (Caused by SSLError(SSLEOFError(8, 'EOF occurred in violation of protocol (_ssl.c:1131)')))
2022-02-22 23:42:05,484 ERROR   Thread-20 :20604 [internal_api.py:upload_file():1576] upload_file request headers: {'User-Agent': 'python-requests/2.25.1', 'Accept-Encoding': 'gzip, deflate', 'Accept': '*/*', 'Connection': 'keep-alive', 'Content-Length': '561'}
2022-02-22 23:42:05,484 ERROR   Thread-20 :20604 [internal_api.py:upload_file():1578] upload_file response body: 
2022-02-22 23:42:11,776 DEBUG   HandlerThread:20604 [handler.py:handle_request():130] handle_request: stop_status
2022-02-22 23:42:11,776 DEBUG   SenderThread:20604 [sender.py:send_request():248] send_request: stop_status
2022-02-22 23:42:15,120 ERROR   Thread-20 :20604 [internal_api.py:upload_file():1574] upload_file exception https://storage.googleapis.com/wandb-production.appspot.com/heene/YOLOv5/12vj7711/wandb-metadata.json?Expires=1645630917&GoogleAccessId=wandb-production%40appspot.gserviceaccount.com&Signature=j88Eu9tD9cNM6xXz9C9ZXh24udpgjFtIE8HWtSRnr316PdLJ%2BF615aRVCArBK6M%2Bl5p7VfY81mS4gTmSOCDdTI8nuSCrrljLWWzy5iDoJQEuRKRBy1uT%2Ba9JlRQANDYBQkyH3Xb6yvrQgcrFmL0Xc9lWkAB3wd%2FA6zh5zlm2cFJ7eGvlaD%2BQyDhfhfG%2BgnFa7Y7cP%2FSXg7nn4RKilBt2VOfIb1kYJPR36xOoeKuJO3%2BWvF7xo2Zlpg6%2BtTiD4HKNuO9FOlj4O7BfAerZYPEI5QNFa286yjbRHFr7WJhpGrJSUnGVd4pHXD7mRJDACcpu4SUHPJ3uIt15azbhlhoxHQ%3D%3D: HTTPSConnectionPool(host='storage.googleapis.com', port=443): Max retries exceeded with url: /wandb-production.appspot.com/heene/YOLOv5/12vj7711/wandb-metadata.json?Expires=1645630917&GoogleAccessId=wandb-production%40appspot.gserviceaccount.com&Signature=j88Eu9tD9cNM6xXz9C9ZXh24udpgjFtIE8HWtSRnr316PdLJ%2BF615aRVCArBK6M%2Bl5p7VfY81mS4gTmSOCDdTI8nuSCrrljLWWzy5iDoJQEuRKRBy1uT%2Ba9JlRQANDYBQkyH3Xb6yvrQgcrFmL0Xc9lWkAB3wd%2FA6zh5zlm2cFJ7eGvlaD%2BQyDhfhfG%2BgnFa7Y7cP%2FSXg7nn4RKilBt2VOfIb1kYJPR36xOoeKuJO3%2BWvF7xo2Zlpg6%2BtTiD4HKNuO9FOlj4O7BfAerZYPEI5QNFa286yjbRHFr7WJhpGrJSUnGVd4pHXD7mRJDACcpu4SUHPJ3uIt15azbhlhoxHQ%3D%3D (Caused by SSLError(SSLEOFError(8, 'EOF occurred in violation of protocol (_ssl.c:1131)')))
2022-02-22 23:42:15,120 ERROR   Thread-20 :20604 [internal_api.py:upload_file():1576] upload_file request headers: {'User-Agent': 'python-requests/2.25.1', 'Accept-Encoding': 'gzip, deflate', 'Accept': '*/*', 'Connection': 'keep-alive', 'Content-Length': '561'}
2022-02-22 23:42:15,120 ERROR   Thread-20 :20604 [internal_api.py:upload_file():1578] upload_file response body: 
2022-02-22 23:42:18,234 DEBUG   SenderThread:20604 [sender.py:send():234] send: stats
2022-02-22 23:42:27,144 DEBUG   HandlerThread:20604 [handler.py:handle_request():130] handle_request: stop_status
2022-02-22 23:42:27,144 DEBUG   SenderThread:20604 [sender.py:send_request():248] send_request: stop_status
2022-02-22 23:42:34,714 INFO    Thread-17 :20604 [dir_watcher.py:_on_file_modified():230] file/dir modified: E:\learn\github_project\yolov5-face\wandb\run-20220222_234144-12vj7711\files\output.log
2022-02-22 23:42:34,840 ERROR   Thread-20 :20604 [internal_api.py:upload_file():1574] upload_file exception https://storage.googleapis.com/wandb-production.appspot.com/heene/YOLOv5/12vj7711/wandb-metadata.json?Expires=1645630917&GoogleAccessId=wandb-production%40appspot.gserviceaccount.com&Signature=j88Eu9tD9cNM6xXz9C9ZXh24udpgjFtIE8HWtSRnr316PdLJ%2BF615aRVCArBK6M%2Bl5p7VfY81mS4gTmSOCDdTI8nuSCrrljLWWzy5iDoJQEuRKRBy1uT%2Ba9JlRQANDYBQkyH3Xb6yvrQgcrFmL0Xc9lWkAB3wd%2FA6zh5zlm2cFJ7eGvlaD%2BQyDhfhfG%2BgnFa7Y7cP%2FSXg7nn4RKilBt2VOfIb1kYJPR36xOoeKuJO3%2BWvF7xo2Zlpg6%2BtTiD4HKNuO9FOlj4O7BfAerZYPEI5QNFa286yjbRHFr7WJhpGrJSUnGVd4pHXD7mRJDACcpu4SUHPJ3uIt15azbhlhoxHQ%3D%3D: HTTPSConnectionPool(host='storage.googleapis.com', port=443): Max retries exceeded with url: /wandb-production.appspot.com/heene/YOLOv5/12vj7711/wandb-metadata.json?Expires=1645630917&GoogleAccessId=wandb-production%40appspot.gserviceaccount.com&Signature=j88Eu9tD9cNM6xXz9C9ZXh24udpgjFtIE8HWtSRnr316PdLJ%2BF615aRVCArBK6M%2Bl5p7VfY81mS4gTmSOCDdTI8nuSCrrljLWWzy5iDoJQEuRKRBy1uT%2Ba9JlRQANDYBQkyH3Xb6yvrQgcrFmL0Xc9lWkAB3wd%2FA6zh5zlm2cFJ7eGvlaD%2BQyDhfhfG%2BgnFa7Y7cP%2FSXg7nn4RKilBt2VOfIb1kYJPR36xOoeKuJO3%2BWvF7xo2Zlpg6%2BtTiD4HKNuO9FOlj4O7BfAerZYPEI5QNFa286yjbRHFr7WJhpGrJSUnGVd4pHXD7mRJDACcpu4SUHPJ3uIt15azbhlhoxHQ%3D%3D (Caused by SSLError(SSLEOFError(8, 'EOF occurred in violation of protocol (_ssl.c:1131)')))
2022-02-22 23:42:34,840 ERROR   Thread-20 :20604 [internal_api.py:upload_file():1576] upload_file request headers: {'User-Agent': 'python-requests/2.25.1', 'Accept-Encoding': 'gzip, deflate', 'Accept': '*/*', 'Connection': 'keep-alive', 'Content-Length': '561'}
2022-02-22 23:42:34,841 ERROR   Thread-20 :20604 [internal_api.py:upload_file():1578] upload_file response body: 
2022-02-22 23:42:42,510 DEBUG   HandlerThread:20604 [handler.py:handle_request():130] handle_request: stop_status
2022-02-22 23:42:42,510 DEBUG   SenderThread:20604 [sender.py:send_request():248] send_request: stop_status
2022-02-22 23:42:49,332 DEBUG   SenderThread:20604 [sender.py:send():234] send: stats
2022-02-22 23:42:57,904 DEBUG   HandlerThread:20604 [handler.py:handle_request():130] handle_request: stop_status
2022-02-22 23:42:57,904 DEBUG   SenderThread:20604 [sender.py:send_request():248] send_request: stop_status
2022-02-22 23:43:05,764 INFO    Thread-17 :20604 [dir_watcher.py:_on_file_modified():230] file/dir modified: E:\learn\github_project\yolov5-face\wandb\run-20220222_234144-12vj7711\files\output.log
2022-02-22 23:43:08,689 DEBUG   SenderThread:20604 [sender.py:send():234] send: files
2022-02-22 23:43:08,689 INFO    SenderThread:20604 [sender.py:_save_file():939] saving file media\images\Labels_0_0.jpg with policy now
2022-02-22 23:43:08,692 DEBUG   SenderThread:20604 [sender.py:send():234] send: files
2022-02-22 23:43:08,692 INFO    SenderThread:20604 [sender.py:_save_file():939] saving file media\images\Labels_0_1.jpg with policy now
2022-02-22 23:43:08,721 DEBUG   SenderThread:20604 [sender.py:send():234] send: history
2022-02-22 23:43:08,721 DEBUG   SenderThread:20604 [sender.py:send():234] send: summary
2022-02-22 23:43:08,723 INFO    SenderThread:20604 [sender.py:_save_file():939] saving file wandb-summary.json with policy end
2022-02-22 23:43:08,769 INFO    Thread-17 :20604 [dir_watcher.py:_on_file_modified():230] file/dir modified: E:\learn\github_project\yolov5-face\wandb\run-20220222_234144-12vj7711\files\wandb-summary.json
2022-02-22 23:43:08,770 INFO    Thread-17 :20604 [dir_watcher.py:_on_file_created():217] file/dir created: E:\learn\github_project\yolov5-face\wandb\run-20220222_234144-12vj7711\files\media\images\Labels_0_1.jpg
2022-02-22 23:43:08,770 INFO    Thread-17 :20604 [dir_watcher.py:_on_file_created():217] file/dir created: E:\learn\github_project\yolov5-face\wandb\run-20220222_234144-12vj7711\files\media\images\Labels_0_0.jpg
2022-02-22 23:43:08,771 INFO    Thread-17 :20604 [dir_watcher.py:_on_file_created():217] file/dir created: E:\learn\github_project\yolov5-face\wandb\run-20220222_234144-12vj7711\files\media
2022-02-22 23:43:08,772 INFO    Thread-17 :20604 [dir_watcher.py:_on_file_created():217] file/dir created: E:\learn\github_project\yolov5-face\wandb\run-20220222_234144-12vj7711\files\media\images
2022-02-22 23:43:09,155 ERROR   Thread-21 :20604 [internal_api.py:upload_file():1574] upload_file exception https://storage.googleapis.com/wandb-production.appspot.com/heene/YOLOv5/12vj7711/media/images/Labels_0_0.jpg?Expires=1645630989&GoogleAccessId=wandb-production%40appspot.gserviceaccount.com&Signature=aFCdLTg8zDAOvddversBSj3rDUctkLqctvMg0BV4HwDed9V5R86Lv2hNl1C41jr2yQIzxpRTXEXnvDxC3KfVC8jQFzg4%2Bx9chqXU9NoNZamxUcX5nnZ1cibpX8zm8rM5z3aOvrmcea6WaV9K8c4MMgXOpc%2BJbMzQNDAT6xo3G8RptBpG1W7cUuFaCwJTOSXzSD9ZQZ6Y%2BezzwxhVSIqLNbHbN%2Bbs6GCrgq%2B6OIcjUnoCfsoLd6a1zaklccI6iSSFfhsUEGP7yBqbotMOk%2Bc6w%2BDN6kdhxb7S5vUkxHFWm76%2BdHTp9T1W52noahu1DcH6RohIrpJ20RRH1SBRLfY91w%3D%3D: HTTPSConnectionPool(host='storage.googleapis.com', port=443): Max retries exceeded with url: /wandb-production.appspot.com/heene/YOLOv5/12vj7711/media/images/Labels_0_0.jpg?Expires=1645630989&GoogleAccessId=wandb-production%40appspot.gserviceaccount.com&Signature=aFCdLTg8zDAOvddversBSj3rDUctkLqctvMg0BV4HwDed9V5R86Lv2hNl1C41jr2yQIzxpRTXEXnvDxC3KfVC8jQFzg4%2Bx9chqXU9NoNZamxUcX5nnZ1cibpX8zm8rM5z3aOvrmcea6WaV9K8c4MMgXOpc%2BJbMzQNDAT6xo3G8RptBpG1W7cUuFaCwJTOSXzSD9ZQZ6Y%2BezzwxhVSIqLNbHbN%2Bbs6GCrgq%2B6OIcjUnoCfsoLd6a1zaklccI6iSSFfhsUEGP7yBqbotMOk%2Bc6w%2BDN6kdhxb7S5vUkxHFWm76%2BdHTp9T1W52noahu1DcH6RohIrpJ20RRH1SBRLfY91w%3D%3D (Caused by SSLError(SSLEOFError(8, 'EOF occurred in violation of protocol (_ssl.c:1131)')))
2022-02-22 23:43:09,156 ERROR   Thread-21 :20604 [internal_api.py:upload_file():1576] upload_file request headers: {'User-Agent': 'python-requests/2.25.1', 'Accept-Encoding': 'gzip, deflate', 'Accept': '*/*', 'Connection': 'keep-alive', 'Content-Length': '133922'}
2022-02-22 23:43:09,156 ERROR   Thread-21 :20604 [internal_api.py:upload_file():1578] upload_file response body: 
2022-02-22 23:43:09,156 ERROR   Thread-22 :20604 [internal_api.py:upload_file():1574] upload_file exception https://storage.googleapis.com/wandb-production.appspot.com/heene/YOLOv5/12vj7711/media/images/Labels_0_1.jpg?Expires=1645630989&GoogleAccessId=wandb-production%40appspot.gserviceaccount.com&Signature=NJsHSLFOrs79Bmc3wSa6CPIZ7%2Ff0RBPbgLPYHxB7%2BvDXT%2FVXYK%2BE5URi%2Bn1KKk40LzGu0h0Kz%2BhIfIdwTO8KWp6NCniboqlzWJfblBhNv7m8yOmCjbGEDSFqUuJe%2F1ok%2F0rlmQvFCq2O8U8E%2BKKzF5nwm1WYttlYqliHY1Ok0UIiBKcQ4w7eo6I2i7CJaVhWfZvOSGprg4yccgWfsstenc%2BqdXJ0DHvEWr59bQR03FdAspvDiI5sIkI%2FfBkKcS5og3qn4x0%2FX1ILVRzFgeKeQWcNXWRJrw%2FLYPyXgG6sI0y2%2FXXEI5lpqDqNNoN57ChAiD431K%2BugYAPtACQxy%2FAdg%3D%3D: HTTPSConnectionPool(host='storage.googleapis.com', port=443): Max retries exceeded with url: /wandb-production.appspot.com/heene/YOLOv5/12vj7711/media/images/Labels_0_1.jpg?Expires=1645630989&GoogleAccessId=wandb-production%40appspot.gserviceaccount.com&Signature=NJsHSLFOrs79Bmc3wSa6CPIZ7%2Ff0RBPbgLPYHxB7%2BvDXT%2FVXYK%2BE5URi%2Bn1KKk40LzGu0h0Kz%2BhIfIdwTO8KWp6NCniboqlzWJfblBhNv7m8yOmCjbGEDSFqUuJe%2F1ok%2F0rlmQvFCq2O8U8E%2BKKzF5nwm1WYttlYqliHY1Ok0UIiBKcQ4w7eo6I2i7CJaVhWfZvOSGprg4yccgWfsstenc%2BqdXJ0DHvEWr59bQR03FdAspvDiI5sIkI%2FfBkKcS5og3qn4x0%2FX1ILVRzFgeKeQWcNXWRJrw%2FLYPyXgG6sI0y2%2FXXEI5lpqDqNNoN57ChAiD431K%2BugYAPtACQxy%2FAdg%3D%3D (Caused by SSLError(SSLEOFError(8, 'EOF occurred in violation of protocol (_ssl.c:1131)')))
2022-02-22 23:43:09,157 ERROR   Thread-22 :20604 [internal_api.py:upload_file():1576] upload_file request headers: {'User-Agent': 'python-requests/2.25.1', 'Accept-Encoding': 'gzip, deflate', 'Accept': '*/*', 'Connection': 'keep-alive', 'Content-Length': '299771'}
2022-02-22 23:43:09,157 ERROR   Thread-22 :20604 [internal_api.py:upload_file():1578] upload_file response body: 
2022-02-22 23:43:10,341 ERROR   Thread-22 :20604 [internal_api.py:upload_file():1574] upload_file exception https://storage.googleapis.com/wandb-production.appspot.com/heene/YOLOv5/12vj7711/media/images/Labels_0_1.jpg?Expires=1645630989&GoogleAccessId=wandb-production%40appspot.gserviceaccount.com&Signature=NJsHSLFOrs79Bmc3wSa6CPIZ7%2Ff0RBPbgLPYHxB7%2BvDXT%2FVXYK%2BE5URi%2Bn1KKk40LzGu0h0Kz%2BhIfIdwTO8KWp6NCniboqlzWJfblBhNv7m8yOmCjbGEDSFqUuJe%2F1ok%2F0rlmQvFCq2O8U8E%2BKKzF5nwm1WYttlYqliHY1Ok0UIiBKcQ4w7eo6I2i7CJaVhWfZvOSGprg4yccgWfsstenc%2BqdXJ0DHvEWr59bQR03FdAspvDiI5sIkI%2FfBkKcS5og3qn4x0%2FX1ILVRzFgeKeQWcNXWRJrw%2FLYPyXgG6sI0y2%2FXXEI5lpqDqNNoN57ChAiD431K%2BugYAPtACQxy%2FAdg%3D%3D: HTTPSConnectionPool(host='storage.googleapis.com', port=443): Max retries exceeded with url: /wandb-production.appspot.com/heene/YOLOv5/12vj7711/media/images/Labels_0_1.jpg?Expires=1645630989&GoogleAccessId=wandb-production%40appspot.gserviceaccount.com&Signature=NJsHSLFOrs79Bmc3wSa6CPIZ7%2Ff0RBPbgLPYHxB7%2BvDXT%2FVXYK%2BE5URi%2Bn1KKk40LzGu0h0Kz%2BhIfIdwTO8KWp6NCniboqlzWJfblBhNv7m8yOmCjbGEDSFqUuJe%2F1ok%2F0rlmQvFCq2O8U8E%2BKKzF5nwm1WYttlYqliHY1Ok0UIiBKcQ4w7eo6I2i7CJaVhWfZvOSGprg4yccgWfsstenc%2BqdXJ0DHvEWr59bQR03FdAspvDiI5sIkI%2FfBkKcS5og3qn4x0%2FX1ILVRzFgeKeQWcNXWRJrw%2FLYPyXgG6sI0y2%2FXXEI5lpqDqNNoN57ChAiD431K%2BugYAPtACQxy%2FAdg%3D%3D (Caused by SSLError(SSLEOFError(8, 'EOF occurred in violation of protocol (_ssl.c:1131)')))
2022-02-22 23:43:10,341 ERROR   Thread-22 :20604 [internal_api.py:upload_file():1576] upload_file request headers: {'User-Agent': 'python-requests/2.25.1', 'Accept-Encoding': 'gzip, deflate', 'Accept': '*/*', 'Connection': 'keep-alive', 'Content-Length': '299771'}
2022-02-22 23:43:10,341 ERROR   Thread-22 :20604 [internal_api.py:upload_file():1578] upload_file response body: 
2022-02-22 23:43:10,341 ERROR   Thread-22 :20604 [retry.py:__call__():126] Retry attempt failed:
Traceback (most recent call last):
  File "C:\ProgramData\Anaconda3\envs\pytorch171\lib\site-packages\urllib3\connectionpool.py", line 699, in urlopen
    httplib_response = self._make_request(
  File "C:\ProgramData\Anaconda3\envs\pytorch171\lib\site-packages\urllib3\connectionpool.py", line 382, in _make_request
    self._validate_conn(conn)
  File "C:\ProgramData\Anaconda3\envs\pytorch171\lib\site-packages\urllib3\connectionpool.py", line 1010, in _validate_conn
    conn.connect()
  File "C:\ProgramData\Anaconda3\envs\pytorch171\lib\site-packages\urllib3\connection.py", line 416, in connect
    self.sock = ssl_wrap_socket(
  File "C:\ProgramData\Anaconda3\envs\pytorch171\lib\site-packages\urllib3\util\ssl_.py", line 449, in ssl_wrap_socket
    ssl_sock = _ssl_wrap_socket_impl(
  File "C:\ProgramData\Anaconda3\envs\pytorch171\lib\site-packages\urllib3\util\ssl_.py", line 493, in _ssl_wrap_socket_impl
    return ssl_context.wrap_socket(sock, server_hostname=server_hostname)
  File "C:\ProgramData\Anaconda3\envs\pytorch171\lib\ssl.py", line 500, in wrap_socket
    return self.sslsocket_class._create(
  File "C:\ProgramData\Anaconda3\envs\pytorch171\lib\ssl.py", line 1040, in _create
    self.do_handshake()
  File "C:\ProgramData\Anaconda3\envs\pytorch171\lib\ssl.py", line 1309, in do_handshake
    self._sslobj.do_handshake()
ssl.SSLEOFError: EOF occurred in violation of protocol (_ssl.c:1131)

During handling of the above exception, another exception occurred:

Traceback (most recent call last):
  File "C:\ProgramData\Anaconda3\envs\pytorch171\lib\site-packages\requests\adapters.py", line 439, in send
    resp = conn.urlopen(
  File "C:\ProgramData\Anaconda3\envs\pytorch171\lib\site-packages\urllib3\connectionpool.py", line 755, in urlopen
    retries = retries.increment(
  File "C:\ProgramData\Anaconda3\envs\pytorch171\lib\site-packages\urllib3\util\retry.py", line 574, in increment
    raise MaxRetryError(_pool, url, error or ResponseError(cause))
urllib3.exceptions.MaxRetryError: HTTPSConnectionPool(host='storage.googleapis.com', port=443): Max retries exceeded with url: /wandb-production.appspot.com/heene/YOLOv5/12vj7711/media/images/Labels_0_1.jpg?Expires=1645630989&GoogleAccessId=wandb-production%40appspot.gserviceaccount.com&Signature=NJsHSLFOrs79Bmc3wSa6CPIZ7%2Ff0RBPbgLPYHxB7%2BvDXT%2FVXYK%2BE5URi%2Bn1KKk40LzGu0h0Kz%2BhIfIdwTO8KWp6NCniboqlzWJfblBhNv7m8yOmCjbGEDSFqUuJe%2F1ok%2F0rlmQvFCq2O8U8E%2BKKzF5nwm1WYttlYqliHY1Ok0UIiBKcQ4w7eo6I2i7CJaVhWfZvOSGprg4yccgWfsstenc%2BqdXJ0DHvEWr59bQR03FdAspvDiI5sIkI%2FfBkKcS5og3qn4x0%2FX1ILVRzFgeKeQWcNXWRJrw%2FLYPyXgG6sI0y2%2FXXEI5lpqDqNNoN57ChAiD431K%2BugYAPtACQxy%2FAdg%3D%3D (Caused by SSLError(SSLEOFError(8, 'EOF occurred in violation of protocol (_ssl.c:1131)')))

During handling of the above exception, another exception occurred:

Traceback (most recent call last):
  File "C:\ProgramData\Anaconda3\envs\pytorch171\lib\site-packages\wandb\sdk\internal\internal_api.py", line 1571, in upload_file
    response = requests.put(url, data=progress, headers=extra_headers)
  File "C:\ProgramData\Anaconda3\envs\pytorch171\lib\site-packages\requests\api.py", line 134, in put
    return request('put', url, data=data, **kwargs)
  File "C:\ProgramData\Anaconda3\envs\pytorch171\lib\site-packages\requests\api.py", line 61, in request
    return session.request(method=method, url=url, **kwargs)
  File "C:\ProgramData\Anaconda3\envs\pytorch171\lib\site-packages\requests\sessions.py", line 542, in request
    resp = self.send(prep, **send_kwargs)
  File "C:\ProgramData\Anaconda3\envs\pytorch171\lib\site-packages\requests\sessions.py", line 655, in send
    r = adapter.send(request, **kwargs)
  File "C:\ProgramData\Anaconda3\envs\pytorch171\lib\site-packages\requests\adapters.py", line 514, in send
    raise SSLError(e, request=request)
requests.exceptions.SSLError: HTTPSConnectionPool(host='storage.googleapis.com', port=443): Max retries exceeded with url: /wandb-production.appspot.com/heene/YOLOv5/12vj7711/media/images/Labels_0_1.jpg?Expires=1645630989&GoogleAccessId=wandb-production%40appspot.gserviceaccount.com&Signature=NJsHSLFOrs79Bmc3wSa6CPIZ7%2Ff0RBPbgLPYHxB7%2BvDXT%2FVXYK%2BE5URi%2Bn1KKk40LzGu0h0Kz%2BhIfIdwTO8KWp6NCniboqlzWJfblBhNv7m8yOmCjbGEDSFqUuJe%2F1ok%2F0rlmQvFCq2O8U8E%2BKKzF5nwm1WYttlYqliHY1Ok0UIiBKcQ4w7eo6I2i7CJaVhWfZvOSGprg4yccgWfsstenc%2BqdXJ0DHvEWr59bQR03FdAspvDiI5sIkI%2FfBkKcS5og3qn4x0%2FX1ILVRzFgeKeQWcNXWRJrw%2FLYPyXgG6sI0y2%2FXXEI5lpqDqNNoN57ChAiD431K%2BugYAPtACQxy%2FAdg%3D%3D (Caused by SSLError(SSLEOFError(8, 'EOF occurred in violation of protocol (_ssl.c:1131)')))

During handling of the above exception, another exception occurred:

Traceback (most recent call last):
  File "C:\ProgramData\Anaconda3\envs\pytorch171\lib\site-packages\wandb\sdk\lib\retry.py", line 102, in __call__
    result = self._call_fn(*args, **kwargs)
  File "C:\ProgramData\Anaconda3\envs\pytorch171\lib\site-packages\wandb\sdk\internal\internal_api.py", line 1587, in upload_file
    six.reraise(type(e), e, sys.exc_info()[2])
  File "C:\ProgramData\Anaconda3\envs\pytorch171\lib\site-packages\six.py", line 718, in reraise
    raise value.with_traceback(tb)
  File "C:\ProgramData\Anaconda3\envs\pytorch171\lib\site-packages\wandb\sdk\internal\internal_api.py", line 1571, in upload_file
    response = requests.put(url, data=progress, headers=extra_headers)
  File "C:\ProgramData\Anaconda3\envs\pytorch171\lib\site-packages\requests\api.py", line 134, in put
    return request('put', url, data=data, **kwargs)
  File "C:\ProgramData\Anaconda3\envs\pytorch171\lib\site-packages\requests\api.py", line 61, in request
    return session.request(method=method, url=url, **kwargs)
  File "C:\ProgramData\Anaconda3\envs\pytorch171\lib\site-packages\requests\sessions.py", line 542, in request
    resp = self.send(prep, **send_kwargs)
  File "C:\ProgramData\Anaconda3\envs\pytorch171\lib\site-packages\requests\sessions.py", line 655, in send
    r = adapter.send(request, **kwargs)
  File "C:\ProgramData\Anaconda3\envs\pytorch171\lib\site-packages\requests\adapters.py", line 514, in send
    raise SSLError(e, request=request)
wandb.sdk.lib.retry.TransientError: None
2022-02-22 23:43:10,352 ERROR   Thread-21 :20604 [internal_api.py:upload_file():1574] upload_file exception https://storage.googleapis.com/wandb-production.appspot.com/heene/YOLOv5/12vj7711/media/images/Labels_0_0.jpg?Expires=1645630989&GoogleAccessId=wandb-production%40appspot.gserviceaccount.com&Signature=aFCdLTg8zDAOvddversBSj3rDUctkLqctvMg0BV4HwDed9V5R86Lv2hNl1C41jr2yQIzxpRTXEXnvDxC3KfVC8jQFzg4%2Bx9chqXU9NoNZamxUcX5nnZ1cibpX8zm8rM5z3aOvrmcea6WaV9K8c4MMgXOpc%2BJbMzQNDAT6xo3G8RptBpG1W7cUuFaCwJTOSXzSD9ZQZ6Y%2BezzwxhVSIqLNbHbN%2Bbs6GCrgq%2B6OIcjUnoCfsoLd6a1zaklccI6iSSFfhsUEGP7yBqbotMOk%2Bc6w%2BDN6kdhxb7S5vUkxHFWm76%2BdHTp9T1W52noahu1DcH6RohIrpJ20RRH1SBRLfY91w%3D%3D: HTTPSConnectionPool(host='storage.googleapis.com', port=443): Max retries exceeded with url: /wandb-production.appspot.com/heene/YOLOv5/12vj7711/media/images/Labels_0_0.jpg?Expires=1645630989&GoogleAccessId=wandb-production%40appspot.gserviceaccount.com&Signature=aFCdLTg8zDAOvddversBSj3rDUctkLqctvMg0BV4HwDed9V5R86Lv2hNl1C41jr2yQIzxpRTXEXnvDxC3KfVC8jQFzg4%2Bx9chqXU9NoNZamxUcX5nnZ1cibpX8zm8rM5z3aOvrmcea6WaV9K8c4MMgXOpc%2BJbMzQNDAT6xo3G8RptBpG1W7cUuFaCwJTOSXzSD9ZQZ6Y%2BezzwxhVSIqLNbHbN%2Bbs6GCrgq%2B6OIcjUnoCfsoLd6a1zaklccI6iSSFfhsUEGP7yBqbotMOk%2Bc6w%2BDN6kdhxb7S5vUkxHFWm76%2BdHTp9T1W52noahu1DcH6RohIrpJ20RRH1SBRLfY91w%3D%3D (Caused by SSLError(SSLEOFError(8, 'EOF occurred in violation of protocol (_ssl.c:1131)')))
2022-02-22 23:43:10,353 ERROR   Thread-21 :20604 [internal_api.py:upload_file():1576] upload_file request headers: {'User-Agent': 'python-requests/2.25.1', 'Accept-Encoding': 'gzip, deflate', 'Accept': '*/*', 'Connection': 'keep-alive', 'Content-Length': '133922'}
2022-02-22 23:43:10,353 ERROR   Thread-21 :20604 [internal_api.py:upload_file():1578] upload_file response body: 
2022-02-22 23:43:10,353 ERROR   Thread-21 :20604 [retry.py:__call__():126] Retry attempt failed:
Traceback (most recent call last):
  File "C:\ProgramData\Anaconda3\envs\pytorch171\lib\site-packages\urllib3\connectionpool.py", line 699, in urlopen
    httplib_response = self._make_request(
  File "C:\ProgramData\Anaconda3\envs\pytorch171\lib\site-packages\urllib3\connectionpool.py", line 382, in _make_request
    self._validate_conn(conn)
  File "C:\ProgramData\Anaconda3\envs\pytorch171\lib\site-packages\urllib3\connectionpool.py", line 1010, in _validate_conn
    conn.connect()
  File "C:\ProgramData\Anaconda3\envs\pytorch171\lib\site-packages\urllib3\connection.py", line 416, in connect
    self.sock = ssl_wrap_socket(
  File "C:\ProgramData\Anaconda3\envs\pytorch171\lib\site-packages\urllib3\util\ssl_.py", line 449, in ssl_wrap_socket
    ssl_sock = _ssl_wrap_socket_impl(
  File "C:\ProgramData\Anaconda3\envs\pytorch171\lib\site-packages\urllib3\util\ssl_.py", line 493, in _ssl_wrap_socket_impl
    return ssl_context.wrap_socket(sock, server_hostname=server_hostname)
  File "C:\ProgramData\Anaconda3\envs\pytorch171\lib\ssl.py", line 500, in wrap_socket
    return self.sslsocket_class._create(
  File "C:\ProgramData\Anaconda3\envs\pytorch171\lib\ssl.py", line 1040, in _create
    self.do_handshake()
  File "C:\ProgramData\Anaconda3\envs\pytorch171\lib\ssl.py", line 1309, in do_handshake
    self._sslobj.do_handshake()
ssl.SSLEOFError: EOF occurred in violation of protocol (_ssl.c:1131)

During handling of the above exception, another exception occurred:

Traceback (most recent call last):
  File "C:\ProgramData\Anaconda3\envs\pytorch171\lib\site-packages\requests\adapters.py", line 439, in send
    resp = conn.urlopen(
  File "C:\ProgramData\Anaconda3\envs\pytorch171\lib\site-packages\urllib3\connectionpool.py", line 755, in urlopen
    retries = retries.increment(
  File "C:\ProgramData\Anaconda3\envs\pytorch171\lib\site-packages\urllib3\util\retry.py", line 574, in increment
    raise MaxRetryError(_pool, url, error or ResponseError(cause))
urllib3.exceptions.MaxRetryError: HTTPSConnectionPool(host='storage.googleapis.com', port=443): Max retries exceeded with url: /wandb-production.appspot.com/heene/YOLOv5/12vj7711/media/images/Labels_0_0.jpg?Expires=1645630989&GoogleAccessId=wandb-production%40appspot.gserviceaccount.com&Signature=aFCdLTg8zDAOvddversBSj3rDUctkLqctvMg0BV4HwDed9V5R86Lv2hNl1C41jr2yQIzxpRTXEXnvDxC3KfVC8jQFzg4%2Bx9chqXU9NoNZamxUcX5nnZ1cibpX8zm8rM5z3aOvrmcea6WaV9K8c4MMgXOpc%2BJbMzQNDAT6xo3G8RptBpG1W7cUuFaCwJTOSXzSD9ZQZ6Y%2BezzwxhVSIqLNbHbN%2Bbs6GCrgq%2B6OIcjUnoCfsoLd6a1zaklccI6iSSFfhsUEGP7yBqbotMOk%2Bc6w%2BDN6kdhxb7S5vUkxHFWm76%2BdHTp9T1W52noahu1DcH6RohIrpJ20RRH1SBRLfY91w%3D%3D (Caused by SSLError(SSLEOFError(8, 'EOF occurred in violation of protocol (_ssl.c:1131)')))

During handling of the above exception, another exception occurred:

Traceback (most recent call last):
  File "C:\ProgramData\Anaconda3\envs\pytorch171\lib\site-packages\wandb\sdk\internal\internal_api.py", line 1571, in upload_file
    response = requests.put(url, data=progress, headers=extra_headers)
  File "C:\ProgramData\Anaconda3\envs\pytorch171\lib\site-packages\requests\api.py", line 134, in put
    return request('put', url, data=data, **kwargs)
  File "C:\ProgramData\Anaconda3\envs\pytorch171\lib\site-packages\requests\api.py", line 61, in request
    return session.request(method=method, url=url, **kwargs)
  File "C:\ProgramData\Anaconda3\envs\pytorch171\lib\site-packages\requests\sessions.py", line 542, in request
    resp = self.send(prep, **send_kwargs)
  File "C:\ProgramData\Anaconda3\envs\pytorch171\lib\site-packages\requests\sessions.py", line 655, in send
    r = adapter.send(request, **kwargs)
  File "C:\ProgramData\Anaconda3\envs\pytorch171\lib\site-packages\requests\adapters.py", line 514, in send
    raise SSLError(e, request=request)
requests.exceptions.SSLError: HTTPSConnectionPool(host='storage.googleapis.com', port=443): Max retries exceeded with url: /wandb-production.appspot.com/heene/YOLOv5/12vj7711/media/images/Labels_0_0.jpg?Expires=1645630989&GoogleAccessId=wandb-production%40appspot.gserviceaccount.com&Signature=aFCdLTg8zDAOvddversBSj3rDUctkLqctvMg0BV4HwDed9V5R86Lv2hNl1C41jr2yQIzxpRTXEXnvDxC3KfVC8jQFzg4%2Bx9chqXU9NoNZamxUcX5nnZ1cibpX8zm8rM5z3aOvrmcea6WaV9K8c4MMgXOpc%2BJbMzQNDAT6xo3G8RptBpG1W7cUuFaCwJTOSXzSD9ZQZ6Y%2BezzwxhVSIqLNbHbN%2Bbs6GCrgq%2B6OIcjUnoCfsoLd6a1zaklccI6iSSFfhsUEGP7yBqbotMOk%2Bc6w%2BDN6kdhxb7S5vUkxHFWm76%2BdHTp9T1W52noahu1DcH6RohIrpJ20RRH1SBRLfY91w%3D%3D (Caused by SSLError(SSLEOFError(8, 'EOF occurred in violation of protocol (_ssl.c:1131)')))

During handling of the above exception, another exception occurred:

Traceback (most recent call last):
  File "C:\ProgramData\Anaconda3\envs\pytorch171\lib\site-packages\wandb\sdk\lib\retry.py", line 102, in __call__
    result = self._call_fn(*args, **kwargs)
  File "C:\ProgramData\Anaconda3\envs\pytorch171\lib\site-packages\wandb\sdk\internal\internal_api.py", line 1587, in upload_file
    six.reraise(type(e), e, sys.exc_info()[2])
  File "C:\ProgramData\Anaconda3\envs\pytorch171\lib\site-packages\six.py", line 718, in reraise
    raise value.with_traceback(tb)
  File "C:\ProgramData\Anaconda3\envs\pytorch171\lib\site-packages\wandb\sdk\internal\internal_api.py", line 1571, in upload_file
    response = requests.put(url, data=progress, headers=extra_headers)
  File "C:\ProgramData\Anaconda3\envs\pytorch171\lib\site-packages\requests\api.py", line 134, in put
    return request('put', url, data=data, **kwargs)
  File "C:\ProgramData\Anaconda3\envs\pytorch171\lib\site-packages\requests\api.py", line 61, in request
    return session.request(method=method, url=url, **kwargs)
  File "C:\ProgramData\Anaconda3\envs\pytorch171\lib\site-packages\requests\sessions.py", line 542, in request
    resp = self.send(prep, **send_kwargs)
  File "C:\ProgramData\Anaconda3\envs\pytorch171\lib\site-packages\requests\sessions.py", line 655, in send
    r = adapter.send(request, **kwargs)
  File "C:\ProgramData\Anaconda3\envs\pytorch171\lib\site-packages\requests\adapters.py", line 514, in send
    raise SSLError(e, request=request)
wandb.sdk.lib.retry.TransientError: None
2022-02-22 23:43:10,775 INFO    Thread-17 :20604 [dir_watcher.py:_on_file_modified():230] file/dir modified: E:\learn\github_project\yolov5-face\wandb\run-20220222_234144-12vj7711\files\output.log
2022-02-22 23:43:10,913 ERROR   Thread-20 :20604 [internal_api.py:upload_file():1574] upload_file exception https://storage.googleapis.com/wandb-production.appspot.com/heene/YOLOv5/12vj7711/wandb-metadata.json?Expires=1645630917&GoogleAccessId=wandb-production%40appspot.gserviceaccount.com&Signature=j88Eu9tD9cNM6xXz9C9ZXh24udpgjFtIE8HWtSRnr316PdLJ%2BF615aRVCArBK6M%2Bl5p7VfY81mS4gTmSOCDdTI8nuSCrrljLWWzy5iDoJQEuRKRBy1uT%2Ba9JlRQANDYBQkyH3Xb6yvrQgcrFmL0Xc9lWkAB3wd%2FA6zh5zlm2cFJ7eGvlaD%2BQyDhfhfG%2BgnFa7Y7cP%2FSXg7nn4RKilBt2VOfIb1kYJPR36xOoeKuJO3%2BWvF7xo2Zlpg6%2BtTiD4HKNuO9FOlj4O7BfAerZYPEI5QNFa286yjbRHFr7WJhpGrJSUnGVd4pHXD7mRJDACcpu4SUHPJ3uIt15azbhlhoxHQ%3D%3D: HTTPSConnectionPool(host='storage.googleapis.com', port=443): Max retries exceeded with url: /wandb-production.appspot.com/heene/YOLOv5/12vj7711/wandb-metadata.json?Expires=1645630917&GoogleAccessId=wandb-production%40appspot.gserviceaccount.com&Signature=j88Eu9tD9cNM6xXz9C9ZXh24udpgjFtIE8HWtSRnr316PdLJ%2BF615aRVCArBK6M%2Bl5p7VfY81mS4gTmSOCDdTI8nuSCrrljLWWzy5iDoJQEuRKRBy1uT%2Ba9JlRQANDYBQkyH3Xb6yvrQgcrFmL0Xc9lWkAB3wd%2FA6zh5zlm2cFJ7eGvlaD%2BQyDhfhfG%2BgnFa7Y7cP%2FSXg7nn4RKilBt2VOfIb1kYJPR36xOoeKuJO3%2BWvF7xo2Zlpg6%2BtTiD4HKNuO9FOlj4O7BfAerZYPEI5QNFa286yjbRHFr7WJhpGrJSUnGVd4pHXD7mRJDACcpu4SUHPJ3uIt15azbhlhoxHQ%3D%3D (Caused by SSLError(SSLEOFError(8, 'EOF occurred in violation of protocol (_ssl.c:1131)')))
2022-02-22 23:43:10,913 ERROR   Thread-20 :20604 [internal_api.py:upload_file():1576] upload_file request headers: {'User-Agent': 'python-requests/2.25.1', 'Accept-Encoding': 'gzip, deflate', 'Accept': '*/*', 'Connection': 'keep-alive', 'Content-Length': '561'}
2022-02-22 23:43:10,913 ERROR   Thread-20 :20604 [internal_api.py:upload_file():1578] upload_file response body: 
2022-02-22 23:43:12,709 ERROR   Thread-22 :20604 [internal_api.py:upload_file():1574] upload_file exception https://storage.googleapis.com/wandb-production.appspot.com/heene/YOLOv5/12vj7711/media/images/Labels_0_1.jpg?Expires=1645630989&GoogleAccessId=wandb-production%40appspot.gserviceaccount.com&Signature=NJsHSLFOrs79Bmc3wSa6CPIZ7%2Ff0RBPbgLPYHxB7%2BvDXT%2FVXYK%2BE5URi%2Bn1KKk40LzGu0h0Kz%2BhIfIdwTO8KWp6NCniboqlzWJfblBhNv7m8yOmCjbGEDSFqUuJe%2F1ok%2F0rlmQvFCq2O8U8E%2BKKzF5nwm1WYttlYqliHY1Ok0UIiBKcQ4w7eo6I2i7CJaVhWfZvOSGprg4yccgWfsstenc%2BqdXJ0DHvEWr59bQR03FdAspvDiI5sIkI%2FfBkKcS5og3qn4x0%2FX1ILVRzFgeKeQWcNXWRJrw%2FLYPyXgG6sI0y2%2FXXEI5lpqDqNNoN57ChAiD431K%2BugYAPtACQxy%2FAdg%3D%3D: HTTPSConnectionPool(host='storage.googleapis.com', port=443): Max retries exceeded with url: /wandb-production.appspot.com/heene/YOLOv5/12vj7711/media/images/Labels_0_1.jpg?Expires=1645630989&GoogleAccessId=wandb-production%40appspot.gserviceaccount.com&Signature=NJsHSLFOrs79Bmc3wSa6CPIZ7%2Ff0RBPbgLPYHxB7%2BvDXT%2FVXYK%2BE5URi%2Bn1KKk40LzGu0h0Kz%2BhIfIdwTO8KWp6NCniboqlzWJfblBhNv7m8yOmCjbGEDSFqUuJe%2F1ok%2F0rlmQvFCq2O8U8E%2BKKzF5nwm1WYttlYqliHY1Ok0UIiBKcQ4w7eo6I2i7CJaVhWfZvOSGprg4yccgWfsstenc%2BqdXJ0DHvEWr59bQR03FdAspvDiI5sIkI%2FfBkKcS5og3qn4x0%2FX1ILVRzFgeKeQWcNXWRJrw%2FLYPyXgG6sI0y2%2FXXEI5lpqDqNNoN57ChAiD431K%2BugYAPtACQxy%2FAdg%3D%3D (Caused by SSLError(SSLEOFError(8, 'EOF occurred in violation of protocol (_ssl.c:1131)')))
2022-02-22 23:43:12,709 ERROR   Thread-22 :20604 [internal_api.py:upload_file():1576] upload_file request headers: {'User-Agent': 'python-requests/2.25.1', 'Accept-Encoding': 'gzip, deflate', 'Accept': '*/*', 'Connection': 'keep-alive', 'Content-Length': '299771'}
2022-02-22 23:43:12,709 ERROR   Thread-22 :20604 [internal_api.py:upload_file():1578] upload_file response body: 
2022-02-22 23:43:12,759 ERROR   Thread-21 :20604 [internal_api.py:upload_file():1574] upload_file exception https://storage.googleapis.com/wandb-production.appspot.com/heene/YOLOv5/12vj7711/media/images/Labels_0_0.jpg?Expires=1645630989&GoogleAccessId=wandb-production%40appspot.gserviceaccount.com&Signature=aFCdLTg8zDAOvddversBSj3rDUctkLqctvMg0BV4HwDed9V5R86Lv2hNl1C41jr2yQIzxpRTXEXnvDxC3KfVC8jQFzg4%2Bx9chqXU9NoNZamxUcX5nnZ1cibpX8zm8rM5z3aOvrmcea6WaV9K8c4MMgXOpc%2BJbMzQNDAT6xo3G8RptBpG1W7cUuFaCwJTOSXzSD9ZQZ6Y%2BezzwxhVSIqLNbHbN%2Bbs6GCrgq%2B6OIcjUnoCfsoLd6a1zaklccI6iSSFfhsUEGP7yBqbotMOk%2Bc6w%2BDN6kdhxb7S5vUkxHFWm76%2BdHTp9T1W52noahu1DcH6RohIrpJ20RRH1SBRLfY91w%3D%3D: HTTPSConnectionPool(host='storage.googleapis.com', port=443): Max retries exceeded with url: /wandb-production.appspot.com/heene/YOLOv5/12vj7711/media/images/Labels_0_0.jpg?Expires=1645630989&GoogleAccessId=wandb-production%40appspot.gserviceaccount.com&Signature=aFCdLTg8zDAOvddversBSj3rDUctkLqctvMg0BV4HwDed9V5R86Lv2hNl1C41jr2yQIzxpRTXEXnvDxC3KfVC8jQFzg4%2Bx9chqXU9NoNZamxUcX5nnZ1cibpX8zm8rM5z3aOvrmcea6WaV9K8c4MMgXOpc%2BJbMzQNDAT6xo3G8RptBpG1W7cUuFaCwJTOSXzSD9ZQZ6Y%2BezzwxhVSIqLNbHbN%2Bbs6GCrgq%2B6OIcjUnoCfsoLd6a1zaklccI6iSSFfhsUEGP7yBqbotMOk%2Bc6w%2BDN6kdhxb7S5vUkxHFWm76%2BdHTp9T1W52noahu1DcH6RohIrpJ20RRH1SBRLfY91w%3D%3D (Caused by SSLError(SSLEOFError(8, 'EOF occurred in violation of protocol (_ssl.c:1131)')))
2022-02-22 23:43:12,759 ERROR   Thread-21 :20604 [internal_api.py:upload_file():1576] upload_file request headers: {'User-Agent': 'python-requests/2.25.1', 'Accept-Encoding': 'gzip, deflate', 'Accept': '*/*', 'Connection': 'keep-alive', 'Content-Length': '133922'}
2022-02-22 23:43:12,759 ERROR   Thread-21 :20604 [internal_api.py:upload_file():1578] upload_file response body: 
2022-02-22 23:43:13,288 DEBUG   HandlerThread:20604 [handler.py:handle_request():130] handle_request: stop_status
2022-02-22 23:43:13,289 DEBUG   SenderThread:20604 [sender.py:send_request():248] send_request: stop_status
2022-02-22 23:43:17,087 ERROR   Thread-22 :20604 [internal_api.py:upload_file():1574] upload_file exception https://storage.googleapis.com/wandb-production.appspot.com/heene/YOLOv5/12vj7711/media/images/Labels_0_1.jpg?Expires=1645630989&GoogleAccessId=wandb-production%40appspot.gserviceaccount.com&Signature=NJsHSLFOrs79Bmc3wSa6CPIZ7%2Ff0RBPbgLPYHxB7%2BvDXT%2FVXYK%2BE5URi%2Bn1KKk40LzGu0h0Kz%2BhIfIdwTO8KWp6NCniboqlzWJfblBhNv7m8yOmCjbGEDSFqUuJe%2F1ok%2F0rlmQvFCq2O8U8E%2BKKzF5nwm1WYttlYqliHY1Ok0UIiBKcQ4w7eo6I2i7CJaVhWfZvOSGprg4yccgWfsstenc%2BqdXJ0DHvEWr59bQR03FdAspvDiI5sIkI%2FfBkKcS5og3qn4x0%2FX1ILVRzFgeKeQWcNXWRJrw%2FLYPyXgG6sI0y2%2FXXEI5lpqDqNNoN57ChAiD431K%2BugYAPtACQxy%2FAdg%3D%3D: HTTPSConnectionPool(host='storage.googleapis.com', port=443): Max retries exceeded with url: /wandb-production.appspot.com/heene/YOLOv5/12vj7711/media/images/Labels_0_1.jpg?Expires=1645630989&GoogleAccessId=wandb-production%40appspot.gserviceaccount.com&Signature=NJsHSLFOrs79Bmc3wSa6CPIZ7%2Ff0RBPbgLPYHxB7%2BvDXT%2FVXYK%2BE5URi%2Bn1KKk40LzGu0h0Kz%2BhIfIdwTO8KWp6NCniboqlzWJfblBhNv7m8yOmCjbGEDSFqUuJe%2F1ok%2F0rlmQvFCq2O8U8E%2BKKzF5nwm1WYttlYqliHY1Ok0UIiBKcQ4w7eo6I2i7CJaVhWfZvOSGprg4yccgWfsstenc%2BqdXJ0DHvEWr59bQR03FdAspvDiI5sIkI%2FfBkKcS5og3qn4x0%2FX1ILVRzFgeKeQWcNXWRJrw%2FLYPyXgG6sI0y2%2FXXEI5lpqDqNNoN57ChAiD431K%2BugYAPtACQxy%2FAdg%3D%3D (Caused by SSLError(SSLEOFError(8, 'EOF occurred in violation of protocol (_ssl.c:1131)')))
2022-02-22 23:43:17,087 ERROR   Thread-22 :20604 [internal_api.py:upload_file():1576] upload_file request headers: {'User-Agent': 'python-requests/2.25.1', 'Accept-Encoding': 'gzip, deflate', 'Accept': '*/*', 'Connection': 'keep-alive', 'Content-Length': '299771'}
2022-02-22 23:43:17,087 ERROR   Thread-22 :20604 [internal_api.py:upload_file():1578] upload_file response body: 
2022-02-22 23:43:17,151 ERROR   Thread-21 :20604 [internal_api.py:upload_file():1574] upload_file exception https://storage.googleapis.com/wandb-production.appspot.com/heene/YOLOv5/12vj7711/media/images/Labels_0_0.jpg?Expires=1645630989&GoogleAccessId=wandb-production%40appspot.gserviceaccount.com&Signature=aFCdLTg8zDAOvddversBSj3rDUctkLqctvMg0BV4HwDed9V5R86Lv2hNl1C41jr2yQIzxpRTXEXnvDxC3KfVC8jQFzg4%2Bx9chqXU9NoNZamxUcX5nnZ1cibpX8zm8rM5z3aOvrmcea6WaV9K8c4MMgXOpc%2BJbMzQNDAT6xo3G8RptBpG1W7cUuFaCwJTOSXzSD9ZQZ6Y%2BezzwxhVSIqLNbHbN%2Bbs6GCrgq%2B6OIcjUnoCfsoLd6a1zaklccI6iSSFfhsUEGP7yBqbotMOk%2Bc6w%2BDN6kdhxb7S5vUkxHFWm76%2BdHTp9T1W52noahu1DcH6RohIrpJ20RRH1SBRLfY91w%3D%3D: HTTPSConnectionPool(host='storage.googleapis.com', port=443): Max retries exceeded with url: /wandb-production.appspot.com/heene/YOLOv5/12vj7711/media/images/Labels_0_0.jpg?Expires=1645630989&GoogleAccessId=wandb-production%40appspot.gserviceaccount.com&Signature=aFCdLTg8zDAOvddversBSj3rDUctkLqctvMg0BV4HwDed9V5R86Lv2hNl1C41jr2yQIzxpRTXEXnvDxC3KfVC8jQFzg4%2Bx9chqXU9NoNZamxUcX5nnZ1cibpX8zm8rM5z3aOvrmcea6WaV9K8c4MMgXOpc%2BJbMzQNDAT6xo3G8RptBpG1W7cUuFaCwJTOSXzSD9ZQZ6Y%2BezzwxhVSIqLNbHbN%2Bbs6GCrgq%2B6OIcjUnoCfsoLd6a1zaklccI6iSSFfhsUEGP7yBqbotMOk%2Bc6w%2BDN6kdhxb7S5vUkxHFWm76%2BdHTp9T1W52noahu1DcH6RohIrpJ20RRH1SBRLfY91w%3D%3D (Caused by SSLError(SSLEOFError(8, 'EOF occurred in violation of protocol (_ssl.c:1131)')))
2022-02-22 23:43:17,151 ERROR   Thread-21 :20604 [internal_api.py:upload_file():1576] upload_file request headers: {'User-Agent': 'python-requests/2.25.1', 'Accept-Encoding': 'gzip, deflate', 'Accept': '*/*', 'Connection': 'keep-alive', 'Content-Length': '133922'}
2022-02-22 23:43:17,151 ERROR   Thread-21 :20604 [internal_api.py:upload_file():1578] upload_file response body: 
2022-02-22 23:43:20,498 DEBUG   SenderThread:20604 [sender.py:send():234] send: stats
2022-02-22 23:43:26,089 ERROR   Thread-21 :20604 [internal_api.py:upload_file():1574] upload_file exception https://storage.googleapis.com/wandb-production.appspot.com/heene/YOLOv5/12vj7711/media/images/Labels_0_0.jpg?Expires=1645630989&GoogleAccessId=wandb-production%40appspot.gserviceaccount.com&Signature=aFCdLTg8zDAOvddversBSj3rDUctkLqctvMg0BV4HwDed9V5R86Lv2hNl1C41jr2yQIzxpRTXEXnvDxC3KfVC8jQFzg4%2Bx9chqXU9NoNZamxUcX5nnZ1cibpX8zm8rM5z3aOvrmcea6WaV9K8c4MMgXOpc%2BJbMzQNDAT6xo3G8RptBpG1W7cUuFaCwJTOSXzSD9ZQZ6Y%2BezzwxhVSIqLNbHbN%2Bbs6GCrgq%2B6OIcjUnoCfsoLd6a1zaklccI6iSSFfhsUEGP7yBqbotMOk%2Bc6w%2BDN6kdhxb7S5vUkxHFWm76%2BdHTp9T1W52noahu1DcH6RohIrpJ20RRH1SBRLfY91w%3D%3D: HTTPSConnectionPool(host='storage.googleapis.com', port=443): Max retries exceeded with url: /wandb-production.appspot.com/heene/YOLOv5/12vj7711/media/images/Labels_0_0.jpg?Expires=1645630989&GoogleAccessId=wandb-production%40appspot.gserviceaccount.com&Signature=aFCdLTg8zDAOvddversBSj3rDUctkLqctvMg0BV4HwDed9V5R86Lv2hNl1C41jr2yQIzxpRTXEXnvDxC3KfVC8jQFzg4%2Bx9chqXU9NoNZamxUcX5nnZ1cibpX8zm8rM5z3aOvrmcea6WaV9K8c4MMgXOpc%2BJbMzQNDAT6xo3G8RptBpG1W7cUuFaCwJTOSXzSD9ZQZ6Y%2BezzwxhVSIqLNbHbN%2Bbs6GCrgq%2B6OIcjUnoCfsoLd6a1zaklccI6iSSFfhsUEGP7yBqbotMOk%2Bc6w%2BDN6kdhxb7S5vUkxHFWm76%2BdHTp9T1W52noahu1DcH6RohIrpJ20RRH1SBRLfY91w%3D%3D (Caused by SSLError(SSLEOFError(8, 'EOF occurred in violation of protocol (_ssl.c:1131)')))
2022-02-22 23:43:26,089 ERROR   Thread-21 :20604 [internal_api.py:upload_file():1576] upload_file request headers: {'User-Agent': 'python-requests/2.25.1', 'Accept-Encoding': 'gzip, deflate', 'Accept': '*/*', 'Connection': 'keep-alive', 'Content-Length': '133922'}
2022-02-22 23:43:26,089 ERROR   Thread-21 :20604 [internal_api.py:upload_file():1578] upload_file response body: 
2022-02-22 23:43:26,267 ERROR   Thread-22 :20604 [internal_api.py:upload_file():1574] upload_file exception https://storage.googleapis.com/wandb-production.appspot.com/heene/YOLOv5/12vj7711/media/images/Labels_0_1.jpg?Expires=1645630989&GoogleAccessId=wandb-production%40appspot.gserviceaccount.com&Signature=NJsHSLFOrs79Bmc3wSa6CPIZ7%2Ff0RBPbgLPYHxB7%2BvDXT%2FVXYK%2BE5URi%2Bn1KKk40LzGu0h0Kz%2BhIfIdwTO8KWp6NCniboqlzWJfblBhNv7m8yOmCjbGEDSFqUuJe%2F1ok%2F0rlmQvFCq2O8U8E%2BKKzF5nwm1WYttlYqliHY1Ok0UIiBKcQ4w7eo6I2i7CJaVhWfZvOSGprg4yccgWfsstenc%2BqdXJ0DHvEWr59bQR03FdAspvDiI5sIkI%2FfBkKcS5og3qn4x0%2FX1ILVRzFgeKeQWcNXWRJrw%2FLYPyXgG6sI0y2%2FXXEI5lpqDqNNoN57ChAiD431K%2BugYAPtACQxy%2FAdg%3D%3D: HTTPSConnectionPool(host='storage.googleapis.com', port=443): Max retries exceeded with url: /wandb-production.appspot.com/heene/YOLOv5/12vj7711/media/images/Labels_0_1.jpg?Expires=1645630989&GoogleAccessId=wandb-production%40appspot.gserviceaccount.com&Signature=NJsHSLFOrs79Bmc3wSa6CPIZ7%2Ff0RBPbgLPYHxB7%2BvDXT%2FVXYK%2BE5URi%2Bn1KKk40LzGu0h0Kz%2BhIfIdwTO8KWp6NCniboqlzWJfblBhNv7m8yOmCjbGEDSFqUuJe%2F1ok%2F0rlmQvFCq2O8U8E%2BKKzF5nwm1WYttlYqliHY1Ok0UIiBKcQ4w7eo6I2i7CJaVhWfZvOSGprg4yccgWfsstenc%2BqdXJ0DHvEWr59bQR03FdAspvDiI5sIkI%2FfBkKcS5og3qn4x0%2FX1ILVRzFgeKeQWcNXWRJrw%2FLYPyXgG6sI0y2%2FXXEI5lpqDqNNoN57ChAiD431K%2BugYAPtACQxy%2FAdg%3D%3D (Caused by SSLError(SSLEOFError(8, 'EOF occurred in violation of protocol (_ssl.c:1131)')))
2022-02-22 23:43:26,267 ERROR   Thread-22 :20604 [internal_api.py:upload_file():1576] upload_file request headers: {'User-Agent': 'python-requests/2.25.1', 'Accept-Encoding': 'gzip, deflate', 'Accept': '*/*', 'Connection': 'keep-alive', 'Content-Length': '299771'}
2022-02-22 23:43:26,268 ERROR   Thread-22 :20604 [internal_api.py:upload_file():1578] upload_file response body: 
2022-02-22 23:43:28,648 DEBUG   HandlerThread:20604 [handler.py:handle_request():130] handle_request: stop_status
2022-02-22 23:43:28,648 DEBUG   SenderThread:20604 [sender.py:send_request():248] send_request: stop_status
2022-02-22 23:43:43,958 ERROR   Thread-21 :20604 [internal_api.py:upload_file():1574] upload_file exception https://storage.googleapis.com/wandb-production.appspot.com/heene/YOLOv5/12vj7711/media/images/Labels_0_0.jpg?Expires=1645630989&GoogleAccessId=wandb-production%40appspot.gserviceaccount.com&Signature=aFCdLTg8zDAOvddversBSj3rDUctkLqctvMg0BV4HwDed9V5R86Lv2hNl1C41jr2yQIzxpRTXEXnvDxC3KfVC8jQFzg4%2Bx9chqXU9NoNZamxUcX5nnZ1cibpX8zm8rM5z3aOvrmcea6WaV9K8c4MMgXOpc%2BJbMzQNDAT6xo3G8RptBpG1W7cUuFaCwJTOSXzSD9ZQZ6Y%2BezzwxhVSIqLNbHbN%2Bbs6GCrgq%2B6OIcjUnoCfsoLd6a1zaklccI6iSSFfhsUEGP7yBqbotMOk%2Bc6w%2BDN6kdhxb7S5vUkxHFWm76%2BdHTp9T1W52noahu1DcH6RohIrpJ20RRH1SBRLfY91w%3D%3D: HTTPSConnectionPool(host='storage.googleapis.com', port=443): Max retries exceeded with url: /wandb-production.appspot.com/heene/YOLOv5/12vj7711/media/images/Labels_0_0.jpg?Expires=1645630989&GoogleAccessId=wandb-production%40appspot.gserviceaccount.com&Signature=aFCdLTg8zDAOvddversBSj3rDUctkLqctvMg0BV4HwDed9V5R86Lv2hNl1C41jr2yQIzxpRTXEXnvDxC3KfVC8jQFzg4%2Bx9chqXU9NoNZamxUcX5nnZ1cibpX8zm8rM5z3aOvrmcea6WaV9K8c4MMgXOpc%2BJbMzQNDAT6xo3G8RptBpG1W7cUuFaCwJTOSXzSD9ZQZ6Y%2BezzwxhVSIqLNbHbN%2Bbs6GCrgq%2B6OIcjUnoCfsoLd6a1zaklccI6iSSFfhsUEGP7yBqbotMOk%2Bc6w%2BDN6kdhxb7S5vUkxHFWm76%2BdHTp9T1W52noahu1DcH6RohIrpJ20RRH1SBRLfY91w%3D%3D (Caused by SSLError(SSLEOFError(8, 'EOF occurred in violation of protocol (_ssl.c:1131)')))
2022-02-22 23:43:43,958 ERROR   Thread-21 :20604 [internal_api.py:upload_file():1576] upload_file request headers: {'User-Agent': 'python-requests/2.25.1', 'Accept-Encoding': 'gzip, deflate', 'Accept': '*/*', 'Connection': 'keep-alive', 'Content-Length': '133922'}
2022-02-22 23:43:43,958 ERROR   Thread-21 :20604 [internal_api.py:upload_file():1578] upload_file response body: 
2022-02-22 23:43:44,014 DEBUG   HandlerThread:20604 [handler.py:handle_request():130] handle_request: stop_status
2022-02-22 23:43:44,014 DEBUG   SenderThread:20604 [sender.py:send_request():248] send_request: stop_status
2022-02-22 23:43:45,011 ERROR   Thread-22 :20604 [internal_api.py:upload_file():1574] upload_file exception https://storage.googleapis.com/wandb-production.appspot.com/heene/YOLOv5/12vj7711/media/images/Labels_0_1.jpg?Expires=1645630989&GoogleAccessId=wandb-production%40appspot.gserviceaccount.com&Signature=NJsHSLFOrs79Bmc3wSa6CPIZ7%2Ff0RBPbgLPYHxB7%2BvDXT%2FVXYK%2BE5URi%2Bn1KKk40LzGu0h0Kz%2BhIfIdwTO8KWp6NCniboqlzWJfblBhNv7m8yOmCjbGEDSFqUuJe%2F1ok%2F0rlmQvFCq2O8U8E%2BKKzF5nwm1WYttlYqliHY1Ok0UIiBKcQ4w7eo6I2i7CJaVhWfZvOSGprg4yccgWfsstenc%2BqdXJ0DHvEWr59bQR03FdAspvDiI5sIkI%2FfBkKcS5og3qn4x0%2FX1ILVRzFgeKeQWcNXWRJrw%2FLYPyXgG6sI0y2%2FXXEI5lpqDqNNoN57ChAiD431K%2BugYAPtACQxy%2FAdg%3D%3D: HTTPSConnectionPool(host='storage.googleapis.com', port=443): Max retries exceeded with url: /wandb-production.appspot.com/heene/YOLOv5/12vj7711/media/images/Labels_0_1.jpg?Expires=1645630989&GoogleAccessId=wandb-production%40appspot.gserviceaccount.com&Signature=NJsHSLFOrs79Bmc3wSa6CPIZ7%2Ff0RBPbgLPYHxB7%2BvDXT%2FVXYK%2BE5URi%2Bn1KKk40LzGu0h0Kz%2BhIfIdwTO8KWp6NCniboqlzWJfblBhNv7m8yOmCjbGEDSFqUuJe%2F1ok%2F0rlmQvFCq2O8U8E%2BKKzF5nwm1WYttlYqliHY1Ok0UIiBKcQ4w7eo6I2i7CJaVhWfZvOSGprg4yccgWfsstenc%2BqdXJ0DHvEWr59bQR03FdAspvDiI5sIkI%2FfBkKcS5og3qn4x0%2FX1ILVRzFgeKeQWcNXWRJrw%2FLYPyXgG6sI0y2%2FXXEI5lpqDqNNoN57ChAiD431K%2BugYAPtACQxy%2FAdg%3D%3D (Caused by SSLError(SSLEOFError(8, 'EOF occurred in violation of protocol (_ssl.c:1131)')))
2022-02-22 23:43:45,011 ERROR   Thread-22 :20604 [internal_api.py:upload_file():1576] upload_file request headers: {'User-Agent': 'python-requests/2.25.1', 'Accept-Encoding': 'gzip, deflate', 'Accept': '*/*', 'Connection': 'keep-alive', 'Content-Length': '299771'}
2022-02-22 23:43:45,011 ERROR   Thread-22 :20604 [internal_api.py:upload_file():1578] upload_file response body: 
2022-02-22 23:43:51,537 DEBUG   SenderThread:20604 [sender.py:send():234] send: stats
2022-02-22 23:43:59,384 DEBUG   HandlerThread:20604 [handler.py:handle_request():130] handle_request: stop_status
2022-02-22 23:43:59,384 DEBUG   SenderThread:20604 [sender.py:send_request():248] send_request: stop_status
2022-02-22 23:44:14,800 DEBUG   HandlerThread:20604 [handler.py:handle_request():130] handle_request: stop_status
2022-02-22 23:44:14,800 DEBUG   SenderThread:20604 [sender.py:send_request():248] send_request: stop_status
2022-02-22 23:44:21,081 ERROR   Thread-20 :20604 [internal_api.py:upload_file():1574] upload_file exception https://storage.googleapis.com/wandb-production.appspot.com/heene/YOLOv5/12vj7711/wandb-metadata.json?Expires=1645630917&GoogleAccessId=wandb-production%40appspot.gserviceaccount.com&Signature=j88Eu9tD9cNM6xXz9C9ZXh24udpgjFtIE8HWtSRnr316PdLJ%2BF615aRVCArBK6M%2Bl5p7VfY81mS4gTmSOCDdTI8nuSCrrljLWWzy5iDoJQEuRKRBy1uT%2Ba9JlRQANDYBQkyH3Xb6yvrQgcrFmL0Xc9lWkAB3wd%2FA6zh5zlm2cFJ7eGvlaD%2BQyDhfhfG%2BgnFa7Y7cP%2FSXg7nn4RKilBt2VOfIb1kYJPR36xOoeKuJO3%2BWvF7xo2Zlpg6%2BtTiD4HKNuO9FOlj4O7BfAerZYPEI5QNFa286yjbRHFr7WJhpGrJSUnGVd4pHXD7mRJDACcpu4SUHPJ3uIt15azbhlhoxHQ%3D%3D: HTTPSConnectionPool(host='storage.googleapis.com', port=443): Max retries exceeded with url: /wandb-production.appspot.com/heene/YOLOv5/12vj7711/wandb-metadata.json?Expires=1645630917&GoogleAccessId=wandb-production%40appspot.gserviceaccount.com&Signature=j88Eu9tD9cNM6xXz9C9ZXh24udpgjFtIE8HWtSRnr316PdLJ%2BF615aRVCArBK6M%2Bl5p7VfY81mS4gTmSOCDdTI8nuSCrrljLWWzy5iDoJQEuRKRBy1uT%2Ba9JlRQANDYBQkyH3Xb6yvrQgcrFmL0Xc9lWkAB3wd%2FA6zh5zlm2cFJ7eGvlaD%2BQyDhfhfG%2BgnFa7Y7cP%2FSXg7nn4RKilBt2VOfIb1kYJPR36xOoeKuJO3%2BWvF7xo2Zlpg6%2BtTiD4HKNuO9FOlj4O7BfAerZYPEI5QNFa286yjbRHFr7WJhpGrJSUnGVd4pHXD7mRJDACcpu4SUHPJ3uIt15azbhlhoxHQ%3D%3D (Caused by SSLError(SSLEOFError(8, 'EOF occurred in violation of protocol (_ssl.c:1131)')))
2022-02-22 23:44:21,082 ERROR   Thread-20 :20604 [internal_api.py:upload_file():1576] upload_file request headers: {'User-Agent': 'python-requests/2.25.1', 'Accept-Encoding': 'gzip, deflate', 'Accept': '*/*', 'Connection': 'keep-alive', 'Content-Length': '561'}
2022-02-22 23:44:21,082 ERROR   Thread-20 :20604 [internal_api.py:upload_file():1578] upload_file response body: 
2022-02-22 23:44:21,270 ERROR   Thread-21 :20604 [internal_api.py:upload_file():1574] upload_file exception https://storage.googleapis.com/wandb-production.appspot.com/heene/YOLOv5/12vj7711/media/images/Labels_0_0.jpg?Expires=1645630989&GoogleAccessId=wandb-production%40appspot.gserviceaccount.com&Signature=aFCdLTg8zDAOvddversBSj3rDUctkLqctvMg0BV4HwDed9V5R86Lv2hNl1C41jr2yQIzxpRTXEXnvDxC3KfVC8jQFzg4%2Bx9chqXU9NoNZamxUcX5nnZ1cibpX8zm8rM5z3aOvrmcea6WaV9K8c4MMgXOpc%2BJbMzQNDAT6xo3G8RptBpG1W7cUuFaCwJTOSXzSD9ZQZ6Y%2BezzwxhVSIqLNbHbN%2Bbs6GCrgq%2B6OIcjUnoCfsoLd6a1zaklccI6iSSFfhsUEGP7yBqbotMOk%2Bc6w%2BDN6kdhxb7S5vUkxHFWm76%2BdHTp9T1W52noahu1DcH6RohIrpJ20RRH1SBRLfY91w%3D%3D: HTTPSConnectionPool(host='storage.googleapis.com', port=443): Max retries exceeded with url: /wandb-production.appspot.com/heene/YOLOv5/12vj7711/media/images/Labels_0_0.jpg?Expires=1645630989&GoogleAccessId=wandb-production%40appspot.gserviceaccount.com&Signature=aFCdLTg8zDAOvddversBSj3rDUctkLqctvMg0BV4HwDed9V5R86Lv2hNl1C41jr2yQIzxpRTXEXnvDxC3KfVC8jQFzg4%2Bx9chqXU9NoNZamxUcX5nnZ1cibpX8zm8rM5z3aOvrmcea6WaV9K8c4MMgXOpc%2BJbMzQNDAT6xo3G8RptBpG1W7cUuFaCwJTOSXzSD9ZQZ6Y%2BezzwxhVSIqLNbHbN%2Bbs6GCrgq%2B6OIcjUnoCfsoLd6a1zaklccI6iSSFfhsUEGP7yBqbotMOk%2Bc6w%2BDN6kdhxb7S5vUkxHFWm76%2BdHTp9T1W52noahu1DcH6RohIrpJ20RRH1SBRLfY91w%3D%3D (Caused by SSLError(SSLEOFError(8, 'EOF occurred in violation of protocol (_ssl.c:1131)')))
2022-02-22 23:44:21,270 ERROR   Thread-21 :20604 [internal_api.py:upload_file():1576] upload_file request headers: {'User-Agent': 'python-requests/2.25.1', 'Accept-Encoding': 'gzip, deflate', 'Accept': '*/*', 'Connection': 'keep-alive', 'Content-Length': '133922'}
2022-02-22 23:44:21,271 ERROR   Thread-21 :20604 [internal_api.py:upload_file():1578] upload_file response body: 
2022-02-22 23:44:22,601 DEBUG   SenderThread:20604 [sender.py:send():234] send: stats
2022-02-22 23:44:25,198 INFO    Thread-22 :20604 [upload_job.py:push():137] Uploaded file C:\Users\fanzh\AppData\Local\Temp\tmp9cyauiqwwandb\ub4gpy5j-media/images/Labels_0_1.jpg
2022-02-22 23:44:25,910 INFO    Thread-17 :20604 [dir_watcher.py:_on_file_modified():230] file/dir modified: E:\learn\github_project\yolov5-face\wandb\run-20220222_234144-12vj7711\files\output.log
2022-02-22 23:44:30,169 DEBUG   HandlerThread:20604 [handler.py:handle_request():130] handle_request: stop_status
2022-02-22 23:44:30,169 DEBUG   SenderThread:20604 [sender.py:send_request():248] send_request: stop_status
2022-02-22 23:44:45,559 DEBUG   HandlerThread:20604 [handler.py:handle_request():130] handle_request: stop_status
2022-02-22 23:44:45,559 DEBUG   SenderThread:20604 [sender.py:send_request():248] send_request: stop_status
2022-02-22 23:44:53,795 DEBUG   SenderThread:20604 [sender.py:send():234] send: stats
2022-02-22 23:45:00,947 DEBUG   HandlerThread:20604 [handler.py:handle_request():130] handle_request: stop_status
2022-02-22 23:45:00,947 DEBUG   SenderThread:20604 [sender.py:send_request():248] send_request: stop_status
2022-02-22 23:45:16,361 DEBUG   HandlerThread:20604 [handler.py:handle_request():130] handle_request: stop_status
2022-02-22 23:45:16,361 DEBUG   SenderThread:20604 [sender.py:send_request():248] send_request: stop_status
2022-02-22 23:45:18,557 WARNING MainThread:20604 [internal.py:wandb_internal():146] Internal process interrupt: 1
2022-02-22 23:45:24,594 WARNING MainThread:20604 [internal.py:is_dead():366] Internal process exiting, parent pid 38996 disappeared
2022-02-22 23:45:24,594 ERROR   MainThread:20604 [internal.py:wandb_internal():142] Internal process shutdown.
2022-02-22 23:45:24,782 INFO    SenderThread:20604 [sender.py:finish():1070] shutting down sender
2022-02-22 23:45:24,782 INFO    SenderThread:20604 [dir_watcher.py:finish():283] shutting down directory watcher
2022-02-22 23:45:24,808 INFO    WriterThread:20604 [datastore.py:close():281] close: E:\learn\github_project\yolov5-face\wandb\run-20220222_234144-12vj7711\run-12vj7711.wandb
2022-02-22 23:45:24,945 INFO    SenderThread:20604 [dir_watcher.py:finish():313] scan: E:\learn\github_project\yolov5-face\wandb\run-20220222_234144-12vj7711\files
2022-02-22 23:45:24,945 INFO    SenderThread:20604 [dir_watcher.py:finish():327] scan save: E:\learn\github_project\yolov5-face\wandb\run-20220222_234144-12vj7711\files\conda-environment.yaml conda-environment.yaml
2022-02-22 23:45:24,946 INFO    SenderThread:20604 [dir_watcher.py:finish():327] scan save: E:\learn\github_project\yolov5-face\wandb\run-20220222_234144-12vj7711\files\config.yaml config.yaml
2022-02-22 23:45:24,956 INFO    SenderThread:20604 [dir_watcher.py:finish():327] scan save: E:\learn\github_project\yolov5-face\wandb\run-20220222_234144-12vj7711\files\output.log output.log
2022-02-22 23:45:24,958 INFO    SenderThread:20604 [dir_watcher.py:finish():327] scan save: E:\learn\github_project\yolov5-face\wandb\run-20220222_234144-12vj7711\files\requirements.txt requirements.txt
2022-02-22 23:45:24,976 INFO    SenderThread:20604 [dir_watcher.py:finish():327] scan save: E:\learn\github_project\yolov5-face\wandb\run-20220222_234144-12vj7711\files\wandb-metadata.json wandb-metadata.json
2022-02-22 23:45:24,976 INFO    SenderThread:20604 [dir_watcher.py:finish():327] scan save: E:\learn\github_project\yolov5-face\wandb\run-20220222_234144-12vj7711\files\wandb-summary.json wandb-summary.json
2022-02-22 23:45:24,996 INFO    SenderThread:20604 [dir_watcher.py:finish():327] scan save: E:\learn\github_project\yolov5-face\wandb\run-20220222_234144-12vj7711\files\media\images\Labels_0_0.jpg media\images\Labels_0_0.jpg
2022-02-22 23:45:24,996 INFO    SenderThread:20604 [dir_watcher.py:finish():327] scan save: E:\learn\github_project\yolov5-face\wandb\run-20220222_234144-12vj7711\files\media\images\Labels_0_1.jpg media\images\Labels_0_1.jpg
2022-02-22 23:45:24,996 INFO    SenderThread:20604 [file_pusher.py:finish():177] shutting down file pusher
2022-02-22 23:45:24,997 INFO    SenderThread:20604 [file_pusher.py:join():182] waiting for file pusher
2022-02-22 23:45:25,546 INFO    HandlerThread:20604 [handler.py:finish():731] shutting down handler
2022-02-22 23:45:25,933 INFO    Thread-27 :20604 [upload_job.py:push():137] Uploaded file E:\learn\github_project\yolov5-face\wandb\run-20220222_234144-12vj7711\files\wandb-summary.json
2022-02-22 23:45:25,982 INFO    Thread-23 :20604 [upload_job.py:push():137] Uploaded file E:\learn\github_project\yolov5-face\wandb\run-20220222_234144-12vj7711\files\conda-environment.yaml
2022-02-22 23:45:25,983 INFO    Thread-25 :20604 [upload_job.py:push():137] Uploaded file E:\learn\github_project\yolov5-face\wandb\run-20220222_234144-12vj7711\files\output.log
2022-02-22 23:45:25,984 INFO    Thread-26 :20604 [upload_job.py:push():137] Uploaded file E:\learn\github_project\yolov5-face\wandb\run-20220222_234144-12vj7711\files\requirements.txt
2022-02-22 23:45:26,091 INFO    Thread-24 :20604 [upload_job.py:push():137] Uploaded file E:\learn\github_project\yolov5-face\wandb\run-20220222_234144-12vj7711\files\config.yaml
2022-02-22 23:45:27,054 INFO    Thread-21 :20604 [upload_job.py:push():137] Uploaded file C:\Users\fanzh\AppData\Local\Temp\tmp9cyauiqwwandb\31nr0gpn-media/images/Labels_0_0.jpg
2022-02-22 23:46:52,824 INFO    Thread-20 :20604 [upload_job.py:push():137] Uploaded file C:\Users\fanzh\AppData\Local\Temp\tmp9cyauiqwwandb\hd10x8k8-wandb-metadata.json
2022-02-22 23:46:53,726 INFO    MainThread:20604 [internal.py:handle_exit():77] Internal process exited
