2022-02-22 23:35:33,964 INFO    MainThread:28112 [internal.py:wandb_internal():87] W&B internal server running at pid: 28112, started at: 2022-02-22 23:35:33.963857
2022-02-22 23:35:33,966 INFO    WriterThread:28112 [datastore.py:open_for_write():77] open: E:\learn\github_project\yolov5-face\wandb\run-20220222_233532-akuzynsx\run-akuzynsx.wandb
2022-02-22 23:35:33,967 DEBUG   HandlerThread:28112 [handler.py:handle_request():130] handle_request: check_version
2022-02-22 23:35:33,976 DEBUG   SenderThread:28112 [sender.py:send():234] send: header
2022-02-22 23:35:33,976 DEBUG   SenderThread:28112 [sender.py:send_request():248] send_request: check_version
2022-02-22 23:35:34,007 DEBUG   SenderThread:28112 [sender.py:send():234] send: run
2022-02-22 23:35:34,022 INFO    SenderThread:28112 [sender.py:_maybe_setup_resume():484] checking resume status for None/YOLOv5/akuzynsx
2022-02-22 23:35:37,703 ERROR   SenderThread:28112 [retry.py:__call__():126] Retry attempt failed:
Traceback (most recent call last):
  File "C:\ProgramData\Anaconda3\envs\pytorch171\lib\site-packages\urllib3\connectionpool.py", line 696, in urlopen
    self._prepare_proxy(conn)
  File "C:\ProgramData\Anaconda3\envs\pytorch171\lib\site-packages\urllib3\connectionpool.py", line 964, in _prepare_proxy
    conn.connect()
  File "C:\ProgramData\Anaconda3\envs\pytorch171\lib\site-packages\urllib3\connection.py", line 364, in connect
    conn = self._connect_tls_proxy(hostname, conn)
  File "C:\ProgramData\Anaconda3\envs\pytorch171\lib\site-packages\urllib3\connection.py", line 501, in _connect_tls_proxy
    socket = ssl_wrap_socket(
  File "C:\ProgramData\Anaconda3\envs\pytorch171\lib\site-packages\urllib3\util\ssl_.py", line 453, in ssl_wrap_socket
    ssl_sock = _ssl_wrap_socket_impl(sock, context, tls_in_tls)
  File "C:\ProgramData\Anaconda3\envs\pytorch171\lib\site-packages\urllib3\util\ssl_.py", line 495, in _ssl_wrap_socket_impl
    return ssl_context.wrap_socket(sock)
  File "C:\ProgramData\Anaconda3\envs\pytorch171\lib\ssl.py", line 500, in wrap_socket
    return self.sslsocket_class._create(
  File "C:\ProgramData\Anaconda3\envs\pytorch171\lib\ssl.py", line 1040, in _create
    self.do_handshake()
  File "C:\ProgramData\Anaconda3\envs\pytorch171\lib\ssl.py", line 1309, in do_handshake
    self._sslobj.do_handshake()
ssl.SSLEOFError: EOF occurred in violation of protocol (_ssl.c:1131)

During handling of the above exception, another exception occurred:

Traceback (most recent call last):
  File "C:\ProgramData\Anaconda3\envs\pytorch171\lib\site-packages\requests\adapters.py", line 439, in send
    resp = conn.urlopen(
  File "C:\ProgramData\Anaconda3\envs\pytorch171\lib\site-packages\urllib3\connectionpool.py", line 755, in urlopen
    retries = retries.increment(
  File "C:\ProgramData\Anaconda3\envs\pytorch171\lib\site-packages\urllib3\util\retry.py", line 574, in increment
    raise MaxRetryError(_pool, url, error or ResponseError(cause))
urllib3.exceptions.MaxRetryError: HTTPSConnectionPool(host='api.wandb.ai', port=443): Max retries exceeded with url: /graphql (Caused by SSLError(SSLEOFError(8, 'EOF occurred in violation of protocol (_ssl.c:1131)')))

During handling of the above exception, another exception occurred:

Traceback (most recent call last):
  File "C:\ProgramData\Anaconda3\envs\pytorch171\lib\site-packages\wandb\sdk\lib\retry.py", line 102, in __call__
    result = self._call_fn(*args, **kwargs)
  File "C:\ProgramData\Anaconda3\envs\pytorch171\lib\site-packages\wandb\sdk\internal\internal_api.py", line 141, in execute
    return self.client.execute(*args, **kwargs)
  File "C:\ProgramData\Anaconda3\envs\pytorch171\lib\site-packages\wandb\vendor\gql-0.2.0\gql\client.py", line 52, in execute
    result = self._get_result(document, *args, **kwargs)
  File "C:\ProgramData\Anaconda3\envs\pytorch171\lib\site-packages\wandb\vendor\gql-0.2.0\gql\client.py", line 60, in _get_result
    return self.transport.execute(document, *args, **kwargs)
  File "C:\ProgramData\Anaconda3\envs\pytorch171\lib\site-packages\wandb\vendor\gql-0.2.0\gql\transport\requests.py", line 38, in execute
    request = requests.post(self.url, **post_args)
  File "C:\ProgramData\Anaconda3\envs\pytorch171\lib\site-packages\requests\api.py", line 119, in post
    return request('post', url, data=data, json=json, **kwargs)
  File "C:\ProgramData\Anaconda3\envs\pytorch171\lib\site-packages\requests\api.py", line 61, in request
    return session.request(method=method, url=url, **kwargs)
  File "C:\ProgramData\Anaconda3\envs\pytorch171\lib\site-packages\requests\sessions.py", line 542, in request
    resp = self.send(prep, **send_kwargs)
  File "C:\ProgramData\Anaconda3\envs\pytorch171\lib\site-packages\requests\sessions.py", line 655, in send
    r = adapter.send(request, **kwargs)
  File "C:\ProgramData\Anaconda3\envs\pytorch171\lib\site-packages\requests\adapters.py", line 514, in send
    raise SSLError(e, request=request)
requests.exceptions.SSLError: HTTPSConnectionPool(host='api.wandb.ai', port=443): Max retries exceeded with url: /graphql (Caused by SSLError(SSLEOFError(8, 'EOF occurred in violation of protocol (_ssl.c:1131)')))
2022-02-22 23:36:04,006 DEBUG   HandlerThread:28112 [handler.py:handle_request():130] handle_request: shutdown
2022-02-22 23:36:04,006 INFO    HandlerThread:28112 [handler.py:finish():731] shutting down handler
2022-02-22 23:36:04,022 INFO    WriterThread:28112 [datastore.py:close():281] close: E:\learn\github_project\yolov5-face\wandb\run-20220222_233532-akuzynsx\run-akuzynsx.wandb
2022-02-22 23:36:47,169 INFO    SenderThread:28112 [dir_watcher.py:__init__():169] watching files in: E:\learn\github_project\yolov5-face\wandb\run-20220222_233532-akuzynsx\files
2022-02-22 23:36:47,169 INFO    SenderThread:28112 [sender.py:_start_run_threads():804] run started: akuzynsx with start time 1645544132
2022-02-22 23:36:47,169 INFO    SenderThread:28112 [sender.py:finish():1070] shutting down sender
2022-02-22 23:36:47,169 INFO    SenderThread:28112 [dir_watcher.py:finish():283] shutting down directory watcher
2022-02-22 23:36:48,170 INFO    SenderThread:28112 [dir_watcher.py:finish():313] scan: E:\learn\github_project\yolov5-face\wandb\run-20220222_233532-akuzynsx\files
2022-02-22 23:36:48,170 INFO    SenderThread:28112 [dir_watcher.py:finish():327] scan save: E:\learn\github_project\yolov5-face\wandb\run-20220222_233532-akuzynsx\files\config.yaml config.yaml
2022-02-22 23:36:48,171 INFO    SenderThread:28112 [file_pusher.py:finish():177] shutting down file pusher
2022-02-22 23:36:48,171 INFO    SenderThread:28112 [file_pusher.py:join():182] waiting for file pusher
2022-02-22 23:36:49,164 INFO    Thread-14 :28112 [upload_job.py:push():137] Uploaded file E:\learn\github_project\yolov5-face\wandb\run-20220222_233532-akuzynsx\files\config.yaml
